INFO 2024-01-29 20:53:44,013 autoreload 12332 33020 H:\web\django\lesson_1\myapp\urls.py changed, reloading.
INFO 2024-01-29 20:53:45,117 autoreload 2856 11780 Watching for file changes with StatReloader
ERROR 2024-01-29 20:53:46,435 log 2856 15392 Internal Server Error: /
Traceback (most recent call last):
  File "C:\Users\pk\anaconda3\envs\django\Lib\site-packages\django\core\handlers\exception.py", line 55, in inner
    response = get_response(request)
               ^^^^^^^^^^^^^^^^^^^^^
  File "C:\Users\pk\anaconda3\envs\django\Lib\site-packages\django\core\handlers\base.py", line 197, in _get_response
    response = wrapped_callback(request, *callback_args, **callback_kwargs)
               ^^^^^^^^^^^^^^^^^^^^^^^^^^^^^^^^^^^^^^^^^^^^^^^^^^^^^^^^^^^^
  File "H:\web\django\lesson_1\myapp\views.py", line 58, in homepage
    return render(request, 'homepage.html', context)
           ^^^^^^^^^^^^^^^^^^^^^^^^^^^^^^^^^^^^^^^^^
  File "C:\Users\pk\anaconda3\envs\django\Lib\site-packages\django\shortcuts.py", line 24, in render
    content = loader.render_to_string(template_name, context, request, using=using)
              ^^^^^^^^^^^^^^^^^^^^^^^^^^^^^^^^^^^^^^^^^^^^^^^^^^^^^^^^^^^^^^^^^^^^^
  File "C:\Users\pk\anaconda3\envs\django\Lib\site-packages\django\template\loader.py", line 62, in render_to_string
    return template.render(context, request)
           ^^^^^^^^^^^^^^^^^^^^^^^^^^^^^^^^^
  File "C:\Users\pk\anaconda3\envs\django\Lib\site-packages\django\template\backends\django.py", line 61, in render
    return self.template.render(context)
           ^^^^^^^^^^^^^^^^^^^^^^^^^^^^^
  File "C:\Users\pk\anaconda3\envs\django\Lib\site-packages\django\template\base.py", line 171, in render
    return self._render(context)
           ^^^^^^^^^^^^^^^^^^^^^
  File "C:\Users\pk\anaconda3\envs\django\Lib\site-packages\django\template\base.py", line 163, in _render
    return self.nodelist.render(context)
           ^^^^^^^^^^^^^^^^^^^^^^^^^^^^^
  File "C:\Users\pk\anaconda3\envs\django\Lib\site-packages\django\template\base.py", line 1000, in render
    return SafeString("".join([node.render_annotated(context) for node in self]))
                               ^^^^^^^^^^^^^^^^^^^^^^^^^^^^^^
  File "C:\Users\pk\anaconda3\envs\django\Lib\site-packages\django\template\base.py", line 961, in render_annotated
    return self.render(context)
           ^^^^^^^^^^^^^^^^^^^^
  File "C:\Users\pk\anaconda3\envs\django\Lib\site-packages\django\template\loader_tags.py", line 159, in render
    return compiled_parent._render(context)
           ^^^^^^^^^^^^^^^^^^^^^^^^^^^^^^^^
  File "C:\Users\pk\anaconda3\envs\django\Lib\site-packages\django\template\base.py", line 163, in _render
    return self.nodelist.render(context)
           ^^^^^^^^^^^^^^^^^^^^^^^^^^^^^
  File "C:\Users\pk\anaconda3\envs\django\Lib\site-packages\django\template\base.py", line 1000, in render
    return SafeString("".join([node.render_annotated(context) for node in self]))
                               ^^^^^^^^^^^^^^^^^^^^^^^^^^^^^^
  File "C:\Users\pk\anaconda3\envs\django\Lib\site-packages\django\template\base.py", line 961, in render_annotated
    return self.render(context)
           ^^^^^^^^^^^^^^^^^^^^
  File "C:\Users\pk\anaconda3\envs\django\Lib\site-packages\django\template\loader_tags.py", line 65, in render
    result = block.nodelist.render(context)
             ^^^^^^^^^^^^^^^^^^^^^^^^^^^^^^
  File "C:\Users\pk\anaconda3\envs\django\Lib\site-packages\django\template\base.py", line 1000, in render
    return SafeString("".join([node.render_annotated(context) for node in self]))
                               ^^^^^^^^^^^^^^^^^^^^^^^^^^^^^^
  File "C:\Users\pk\anaconda3\envs\django\Lib\site-packages\django\template\base.py", line 961, in render_annotated
    return self.render(context)
           ^^^^^^^^^^^^^^^^^^^^
  File "C:\Users\pk\anaconda3\envs\django\Lib\site-packages\django\template\defaulttags.py", line 478, in render
    url = reverse(view_name, args=args, kwargs=kwargs, current_app=current_app)
          ^^^^^^^^^^^^^^^^^^^^^^^^^^^^^^^^^^^^^^^^^^^^^^^^^^^^^^^^^^^^^^^^^^^^^
  File "C:\Users\pk\anaconda3\envs\django\Lib\site-packages\django\urls\base.py", line 88, in reverse
    return resolver._reverse_with_prefix(view, prefix, *args, **kwargs)
           ^^^^^^^^^^^^^^^^^^^^^^^^^^^^^^^^^^^^^^^^^^^^^^^^^^^^^^^^^^^^
  File "C:\Users\pk\anaconda3\envs\django\Lib\site-packages\django\urls\resolvers.py", line 848, in _reverse_with_prefix
    raise NoReverseMatch(msg)
django.urls.exceptions.NoReverseMatch: Reverse for 'myapp.views.CustomerCreate' not found. 'myapp.views.CustomerCreate' is not a valid view function or pattern name.
ERROR 2024-01-29 20:53:46,453 basehttp 2856 15392 "GET / HTTP/1.1" 500 148435
WARNING 2024-01-29 20:53:46,506 log 2856 15392 Not Found: /favicon.ico
INFO 2024-01-29 20:53:46,506 basehttp 2856 15392 - Broken pipe from ('127.0.0.1', 50444)
ERROR 2024-01-29 20:54:15,936 log 2856 34100 Internal Server Error: /
Traceback (most recent call last):
  File "C:\Users\pk\anaconda3\envs\django\Lib\site-packages\django\core\handlers\exception.py", line 55, in inner
    response = get_response(request)
               ^^^^^^^^^^^^^^^^^^^^^
  File "C:\Users\pk\anaconda3\envs\django\Lib\site-packages\django\core\handlers\base.py", line 197, in _get_response
    response = wrapped_callback(request, *callback_args, **callback_kwargs)
               ^^^^^^^^^^^^^^^^^^^^^^^^^^^^^^^^^^^^^^^^^^^^^^^^^^^^^^^^^^^^
  File "H:\web\django\lesson_1\myapp\views.py", line 58, in homepage
    return render(request, 'homepage.html', context)
           ^^^^^^^^^^^^^^^^^^^^^^^^^^^^^^^^^^^^^^^^^
  File "C:\Users\pk\anaconda3\envs\django\Lib\site-packages\django\shortcuts.py", line 24, in render
    content = loader.render_to_string(template_name, context, request, using=using)
              ^^^^^^^^^^^^^^^^^^^^^^^^^^^^^^^^^^^^^^^^^^^^^^^^^^^^^^^^^^^^^^^^^^^^^
  File "C:\Users\pk\anaconda3\envs\django\Lib\site-packages\django\template\loader.py", line 62, in render_to_string
    return template.render(context, request)
           ^^^^^^^^^^^^^^^^^^^^^^^^^^^^^^^^^
  File "C:\Users\pk\anaconda3\envs\django\Lib\site-packages\django\template\backends\django.py", line 61, in render
    return self.template.render(context)
           ^^^^^^^^^^^^^^^^^^^^^^^^^^^^^
  File "C:\Users\pk\anaconda3\envs\django\Lib\site-packages\django\template\base.py", line 171, in render
    return self._render(context)
           ^^^^^^^^^^^^^^^^^^^^^
  File "C:\Users\pk\anaconda3\envs\django\Lib\site-packages\django\template\base.py", line 163, in _render
    return self.nodelist.render(context)
           ^^^^^^^^^^^^^^^^^^^^^^^^^^^^^
  File "C:\Users\pk\anaconda3\envs\django\Lib\site-packages\django\template\base.py", line 1000, in render
    return SafeString("".join([node.render_annotated(context) for node in self]))
                               ^^^^^^^^^^^^^^^^^^^^^^^^^^^^^^
  File "C:\Users\pk\anaconda3\envs\django\Lib\site-packages\django\template\base.py", line 961, in render_annotated
    return self.render(context)
           ^^^^^^^^^^^^^^^^^^^^
  File "C:\Users\pk\anaconda3\envs\django\Lib\site-packages\django\template\loader_tags.py", line 159, in render
    return compiled_parent._render(context)
           ^^^^^^^^^^^^^^^^^^^^^^^^^^^^^^^^
  File "C:\Users\pk\anaconda3\envs\django\Lib\site-packages\django\template\base.py", line 163, in _render
    return self.nodelist.render(context)
           ^^^^^^^^^^^^^^^^^^^^^^^^^^^^^
  File "C:\Users\pk\anaconda3\envs\django\Lib\site-packages\django\template\base.py", line 1000, in render
    return SafeString("".join([node.render_annotated(context) for node in self]))
                               ^^^^^^^^^^^^^^^^^^^^^^^^^^^^^^
  File "C:\Users\pk\anaconda3\envs\django\Lib\site-packages\django\template\base.py", line 961, in render_annotated
    return self.render(context)
           ^^^^^^^^^^^^^^^^^^^^
  File "C:\Users\pk\anaconda3\envs\django\Lib\site-packages\django\template\loader_tags.py", line 65, in render
    result = block.nodelist.render(context)
             ^^^^^^^^^^^^^^^^^^^^^^^^^^^^^^
  File "C:\Users\pk\anaconda3\envs\django\Lib\site-packages\django\template\base.py", line 1000, in render
    return SafeString("".join([node.render_annotated(context) for node in self]))
                               ^^^^^^^^^^^^^^^^^^^^^^^^^^^^^^
  File "C:\Users\pk\anaconda3\envs\django\Lib\site-packages\django\template\base.py", line 961, in render_annotated
    return self.render(context)
           ^^^^^^^^^^^^^^^^^^^^
  File "C:\Users\pk\anaconda3\envs\django\Lib\site-packages\django\template\defaulttags.py", line 478, in render
    url = reverse(view_name, args=args, kwargs=kwargs, current_app=current_app)
          ^^^^^^^^^^^^^^^^^^^^^^^^^^^^^^^^^^^^^^^^^^^^^^^^^^^^^^^^^^^^^^^^^^^^^
  File "C:\Users\pk\anaconda3\envs\django\Lib\site-packages\django\urls\base.py", line 88, in reverse
    return resolver._reverse_with_prefix(view, prefix, *args, **kwargs)
           ^^^^^^^^^^^^^^^^^^^^^^^^^^^^^^^^^^^^^^^^^^^^^^^^^^^^^^^^^^^^
  File "C:\Users\pk\anaconda3\envs\django\Lib\site-packages\django\urls\resolvers.py", line 848, in _reverse_with_prefix
    raise NoReverseMatch(msg)
django.urls.exceptions.NoReverseMatch: Reverse for 'myapp.views.create_customer' not found. 'myapp.views.create_customer' is not a valid view function or pattern name.
ERROR 2024-01-29 20:54:15,954 basehttp 2856 34100 "GET / HTTP/1.1" 500 148461
INFO 2024-01-29 20:54:31,482 basehttp 2856 34100 "GET / HTTP/1.1" 200 601
INFO 2024-01-29 20:55:24,894 autoreload 2856 11780 H:\web\django\lesson_1\myapp\urls.py changed, reloading.
INFO 2024-01-29 20:55:28,260 autoreload 1108 29940 Watching for file changes with StatReloader
INFO 2024-01-29 20:55:28,778 basehttp 1108 7316 "GET / HTTP/1.1" 200 711
WARNING 2024-01-29 20:55:28,909 log 1108 7316 Not Found: /favicon.ico
WARNING 2024-01-29 20:55:28,909 basehttp 1108 7316 "GET /favicon.ico HTTP/1.1" 404 4104
ERROR 2024-01-29 20:55:31,214 log 1108 7316 Internal Server Error: /create_customer/
Traceback (most recent call last):
  File "C:\Users\pk\anaconda3\envs\django\Lib\site-packages\django\core\handlers\exception.py", line 55, in inner
    response = get_response(request)
               ^^^^^^^^^^^^^^^^^^^^^
  File "C:\Users\pk\anaconda3\envs\django\Lib\site-packages\django\core\handlers\base.py", line 220, in _get_response
    response = response.render()
               ^^^^^^^^^^^^^^^^^
  File "C:\Users\pk\anaconda3\envs\django\Lib\site-packages\django\template\response.py", line 114, in render
    self.content = self.rendered_content
                   ^^^^^^^^^^^^^^^^^^^^^
  File "C:\Users\pk\anaconda3\envs\django\Lib\site-packages\django\template\response.py", line 90, in rendered_content
    template = self.resolve_template(self.template_name)
               ^^^^^^^^^^^^^^^^^^^^^^^^^^^^^^^^^^^^^^^^^
  File "C:\Users\pk\anaconda3\envs\django\Lib\site-packages\django\template\response.py", line 72, in resolve_template
    return select_template(template, using=self.using)
           ^^^^^^^^^^^^^^^^^^^^^^^^^^^^^^^^^^^^^^^^^^^
  File "C:\Users\pk\anaconda3\envs\django\Lib\site-packages\django\template\loader.py", line 47, in select_template
    raise TemplateDoesNotExist(", ".join(template_name_list), chain=chain)
django.template.exceptions.TemplateDoesNotExist: myapp/customer_form.html
ERROR 2024-01-29 20:55:31,214 basehttp 1108 7316 "GET /create_customer/ HTTP/1.1" 500 81345
ERROR 2024-01-29 21:02:54,260 log 1108 17136 Internal Server Error: /create_customer/
Traceback (most recent call last):
  File "C:\Users\pk\anaconda3\envs\django\Lib\site-packages\django\core\handlers\exception.py", line 55, in inner
    response = get_response(request)
               ^^^^^^^^^^^^^^^^^^^^^
  File "C:\Users\pk\anaconda3\envs\django\Lib\site-packages\django\core\handlers\base.py", line 220, in _get_response
    response = response.render()
               ^^^^^^^^^^^^^^^^^
  File "C:\Users\pk\anaconda3\envs\django\Lib\site-packages\django\template\response.py", line 114, in render
    self.content = self.rendered_content
                   ^^^^^^^^^^^^^^^^^^^^^
  File "C:\Users\pk\anaconda3\envs\django\Lib\site-packages\django\template\response.py", line 90, in rendered_content
    template = self.resolve_template(self.template_name)
               ^^^^^^^^^^^^^^^^^^^^^^^^^^^^^^^^^^^^^^^^^
  File "C:\Users\pk\anaconda3\envs\django\Lib\site-packages\django\template\response.py", line 72, in resolve_template
    return select_template(template, using=self.using)
           ^^^^^^^^^^^^^^^^^^^^^^^^^^^^^^^^^^^^^^^^^^^
  File "C:\Users\pk\anaconda3\envs\django\Lib\site-packages\django\template\loader.py", line 47, in select_template
    raise TemplateDoesNotExist(", ".join(template_name_list), chain=chain)
django.template.exceptions.TemplateDoesNotExist: myapp/customer_form.html
ERROR 2024-01-29 21:02:54,264 basehttp 1108 17136 "GET /create_customer/ HTTP/1.1" 500 81345
WARNING 2024-01-29 21:02:54,324 log 1108 17136 Not Found: /favicon.ico
INFO 2024-01-29 21:02:54,328 basehttp 1108 17136 - Broken pipe from ('127.0.0.1', 52515)
ERROR 2024-01-29 21:03:16,514 log 1108 32808 Internal Server Error: /create_customer/
Traceback (most recent call last):
  File "C:\Users\pk\anaconda3\envs\django\Lib\site-packages\django\core\handlers\exception.py", line 55, in inner
    response = get_response(request)
               ^^^^^^^^^^^^^^^^^^^^^
  File "C:\Users\pk\anaconda3\envs\django\Lib\site-packages\django\core\handlers\base.py", line 220, in _get_response
    response = response.render()
               ^^^^^^^^^^^^^^^^^
  File "C:\Users\pk\anaconda3\envs\django\Lib\site-packages\django\template\response.py", line 114, in render
    self.content = self.rendered_content
                   ^^^^^^^^^^^^^^^^^^^^^
  File "C:\Users\pk\anaconda3\envs\django\Lib\site-packages\django\template\response.py", line 90, in rendered_content
    template = self.resolve_template(self.template_name)
               ^^^^^^^^^^^^^^^^^^^^^^^^^^^^^^^^^^^^^^^^^
  File "C:\Users\pk\anaconda3\envs\django\Lib\site-packages\django\template\response.py", line 72, in resolve_template
    return select_template(template, using=self.using)
           ^^^^^^^^^^^^^^^^^^^^^^^^^^^^^^^^^^^^^^^^^^^
  File "C:\Users\pk\anaconda3\envs\django\Lib\site-packages\django\template\loader.py", line 47, in select_template
    raise TemplateDoesNotExist(", ".join(template_name_list), chain=chain)
django.template.exceptions.TemplateDoesNotExist: myapp/customer_form.html
ERROR 2024-01-29 21:03:16,514 basehttp 1108 32808 "GET /create_customer/ HTTP/1.1" 500 81345
ERROR 2024-01-29 21:03:17,675 log 1108 32808 Internal Server Error: /create_customer/
Traceback (most recent call last):
  File "C:\Users\pk\anaconda3\envs\django\Lib\site-packages\django\core\handlers\exception.py", line 55, in inner
    response = get_response(request)
               ^^^^^^^^^^^^^^^^^^^^^
  File "C:\Users\pk\anaconda3\envs\django\Lib\site-packages\django\core\handlers\base.py", line 220, in _get_response
    response = response.render()
               ^^^^^^^^^^^^^^^^^
  File "C:\Users\pk\anaconda3\envs\django\Lib\site-packages\django\template\response.py", line 114, in render
    self.content = self.rendered_content
                   ^^^^^^^^^^^^^^^^^^^^^
  File "C:\Users\pk\anaconda3\envs\django\Lib\site-packages\django\template\response.py", line 90, in rendered_content
    template = self.resolve_template(self.template_name)
               ^^^^^^^^^^^^^^^^^^^^^^^^^^^^^^^^^^^^^^^^^
  File "C:\Users\pk\anaconda3\envs\django\Lib\site-packages\django\template\response.py", line 72, in resolve_template
    return select_template(template, using=self.using)
           ^^^^^^^^^^^^^^^^^^^^^^^^^^^^^^^^^^^^^^^^^^^
  File "C:\Users\pk\anaconda3\envs\django\Lib\site-packages\django\template\loader.py", line 47, in select_template
    raise TemplateDoesNotExist(", ".join(template_name_list), chain=chain)
django.template.exceptions.TemplateDoesNotExist: myapp/customer_form.html
ERROR 2024-01-29 21:03:17,675 basehttp 1108 32808 "GET /create_customer/ HTTP/1.1" 500 81345
ERROR 2024-01-29 21:03:17,964 log 1108 32808 Internal Server Error: /create_customer/
Traceback (most recent call last):
  File "C:\Users\pk\anaconda3\envs\django\Lib\site-packages\django\core\handlers\exception.py", line 55, in inner
    response = get_response(request)
               ^^^^^^^^^^^^^^^^^^^^^
  File "C:\Users\pk\anaconda3\envs\django\Lib\site-packages\django\core\handlers\base.py", line 220, in _get_response
    response = response.render()
               ^^^^^^^^^^^^^^^^^
  File "C:\Users\pk\anaconda3\envs\django\Lib\site-packages\django\template\response.py", line 114, in render
    self.content = self.rendered_content
                   ^^^^^^^^^^^^^^^^^^^^^
  File "C:\Users\pk\anaconda3\envs\django\Lib\site-packages\django\template\response.py", line 90, in rendered_content
    template = self.resolve_template(self.template_name)
               ^^^^^^^^^^^^^^^^^^^^^^^^^^^^^^^^^^^^^^^^^
  File "C:\Users\pk\anaconda3\envs\django\Lib\site-packages\django\template\response.py", line 72, in resolve_template
    return select_template(template, using=self.using)
           ^^^^^^^^^^^^^^^^^^^^^^^^^^^^^^^^^^^^^^^^^^^
  File "C:\Users\pk\anaconda3\envs\django\Lib\site-packages\django\template\loader.py", line 47, in select_template
    raise TemplateDoesNotExist(", ".join(template_name_list), chain=chain)
django.template.exceptions.TemplateDoesNotExist: myapp/customer_form.html
ERROR 2024-01-29 21:03:17,964 basehttp 1108 32808 "GET /create_customer/ HTTP/1.1" 500 81345
ERROR 2024-01-29 21:03:18,698 log 1108 29644 Internal Server Error: /create_customer/
Traceback (most recent call last):
  File "C:\Users\pk\anaconda3\envs\django\Lib\site-packages\django\core\handlers\exception.py", line 55, in inner
    response = get_response(request)
               ^^^^^^^^^^^^^^^^^^^^^
  File "C:\Users\pk\anaconda3\envs\django\Lib\site-packages\django\core\handlers\base.py", line 220, in _get_response
    response = response.render()
               ^^^^^^^^^^^^^^^^^
  File "C:\Users\pk\anaconda3\envs\django\Lib\site-packages\django\template\response.py", line 114, in render
    self.content = self.rendered_content
                   ^^^^^^^^^^^^^^^^^^^^^
  File "C:\Users\pk\anaconda3\envs\django\Lib\site-packages\django\template\response.py", line 90, in rendered_content
    template = self.resolve_template(self.template_name)
               ^^^^^^^^^^^^^^^^^^^^^^^^^^^^^^^^^^^^^^^^^
  File "C:\Users\pk\anaconda3\envs\django\Lib\site-packages\django\template\response.py", line 72, in resolve_template
    return select_template(template, using=self.using)
           ^^^^^^^^^^^^^^^^^^^^^^^^^^^^^^^^^^^^^^^^^^^
  File "C:\Users\pk\anaconda3\envs\django\Lib\site-packages\django\template\loader.py", line 47, in select_template
    raise TemplateDoesNotExist(", ".join(template_name_list), chain=chain)
django.template.exceptions.TemplateDoesNotExist: myapp/customer_form.html
ERROR 2024-01-29 21:03:18,698 basehttp 1108 29644 "GET /create_customer/ HTTP/1.1" 500 81610
WARNING 2024-01-29 21:03:18,751 log 1108 29644 Not Found: /favicon.ico
WARNING 2024-01-29 21:03:18,751 basehttp 1108 29644 "GET /favicon.ico HTTP/1.1" 404 4104
INFO 2024-01-29 21:03:42,083 basehttp 1108 29644 "GET /create_customer/ HTTP/1.1" 200 1187
INFO 2024-01-29 21:04:22,653 basehttp 1108 29644 "POST /create_customer/ HTTP/1.1" 302 0
INFO 2024-01-29 21:04:22,665 basehttp 1108 29644 "GET / HTTP/1.1" 200 890
INFO 2024-01-29 21:05:19,748 basehttp 1108 29644 "GET /create_product/ HTTP/1.1" 200 1192
ERROR 2024-01-29 21:05:36,183 log 1108 29644 Internal Server Error: /create_product/
Traceback (most recent call last):
  File "C:\Users\pk\anaconda3\envs\django\Lib\site-packages\django\db\backends\utils.py", line 105, in _execute
    return self.cursor.execute(sql, params)
           ^^^^^^^^^^^^^^^^^^^^^^^^^^^^^^^^
  File "C:\Users\pk\anaconda3\envs\django\Lib\site-packages\django\db\backends\sqlite3\base.py", line 328, in execute
    return super().execute(query, params)
           ^^^^^^^^^^^^^^^^^^^^^^^^^^^^^^
sqlite3.IntegrityError: NOT NULL constraint failed: myapp_product.date_added

The above exception was the direct cause of the following exception:

Traceback (most recent call last):
  File "C:\Users\pk\anaconda3\envs\django\Lib\site-packages\django\core\handlers\exception.py", line 55, in inner
    response = get_response(request)
               ^^^^^^^^^^^^^^^^^^^^^
  File "C:\Users\pk\anaconda3\envs\django\Lib\site-packages\django\core\handlers\base.py", line 197, in _get_response
    response = wrapped_callback(request, *callback_args, **callback_kwargs)
               ^^^^^^^^^^^^^^^^^^^^^^^^^^^^^^^^^^^^^^^^^^^^^^^^^^^^^^^^^^^^
  File "C:\Users\pk\anaconda3\envs\django\Lib\site-packages\django\views\generic\base.py", line 104, in view
    return self.dispatch(request, *args, **kwargs)
           ^^^^^^^^^^^^^^^^^^^^^^^^^^^^^^^^^^^^^^^
  File "C:\Users\pk\anaconda3\envs\django\Lib\site-packages\django\views\generic\base.py", line 143, in dispatch
    return handler(request, *args, **kwargs)
           ^^^^^^^^^^^^^^^^^^^^^^^^^^^^^^^^^
  File "C:\Users\pk\anaconda3\envs\django\Lib\site-packages\django\views\generic\edit.py", line 182, in post
    return super().post(request, *args, **kwargs)
           ^^^^^^^^^^^^^^^^^^^^^^^^^^^^^^^^^^^^^^
  File "C:\Users\pk\anaconda3\envs\django\Lib\site-packages\django\views\generic\edit.py", line 151, in post
    return self.form_valid(form)
           ^^^^^^^^^^^^^^^^^^^^^
  File "C:\Users\pk\anaconda3\envs\django\Lib\site-packages\django\views\generic\edit.py", line 133, in form_valid
    self.object = form.save()
                  ^^^^^^^^^^^
  File "C:\Users\pk\anaconda3\envs\django\Lib\site-packages\django\forms\models.py", line 551, in save
    self.instance.save()
  File "C:\Users\pk\anaconda3\envs\django\Lib\site-packages\django\db\models\base.py", line 822, in save
    self.save_base(
  File "C:\Users\pk\anaconda3\envs\django\Lib\site-packages\django\db\models\base.py", line 909, in save_base
    updated = self._save_table(
              ^^^^^^^^^^^^^^^^^
  File "C:\Users\pk\anaconda3\envs\django\Lib\site-packages\django\db\models\base.py", line 1067, in _save_table
    results = self._do_insert(
              ^^^^^^^^^^^^^^^^
  File "C:\Users\pk\anaconda3\envs\django\Lib\site-packages\django\db\models\base.py", line 1108, in _do_insert
    return manager._insert(
           ^^^^^^^^^^^^^^^^
  File "C:\Users\pk\anaconda3\envs\django\Lib\site-packages\django\db\models\manager.py", line 87, in manager_method
    return getattr(self.get_queryset(), name)(*args, **kwargs)
           ^^^^^^^^^^^^^^^^^^^^^^^^^^^^^^^^^^^^^^^^^^^^^^^^^^^
  File "C:\Users\pk\anaconda3\envs\django\Lib\site-packages\django\db\models\query.py", line 1845, in _insert
    return query.get_compiler(using=using).execute_sql(returning_fields)
           ^^^^^^^^^^^^^^^^^^^^^^^^^^^^^^^^^^^^^^^^^^^^^^^^^^^^^^^^^^^^^
  File "C:\Users\pk\anaconda3\envs\django\Lib\site-packages\django\db\models\sql\compiler.py", line 1823, in execute_sql
    cursor.execute(sql, params)
  File "C:\Users\pk\anaconda3\envs\django\Lib\site-packages\django\db\backends\utils.py", line 122, in execute
    return super().execute(sql, params)
           ^^^^^^^^^^^^^^^^^^^^^^^^^^^^
  File "C:\Users\pk\anaconda3\envs\django\Lib\site-packages\django\db\backends\utils.py", line 79, in execute
    return self._execute_with_wrappers(
           ^^^^^^^^^^^^^^^^^^^^^^^^^^^^
  File "C:\Users\pk\anaconda3\envs\django\Lib\site-packages\django\db\backends\utils.py", line 92, in _execute_with_wrappers
    return executor(sql, params, many, context)
           ^^^^^^^^^^^^^^^^^^^^^^^^^^^^^^^^^^^^
  File "C:\Users\pk\anaconda3\envs\django\Lib\site-packages\django\db\backends\utils.py", line 100, in _execute
    with self.db.wrap_database_errors:
  File "C:\Users\pk\anaconda3\envs\django\Lib\site-packages\django\db\utils.py", line 91, in __exit__
    raise dj_exc_value.with_traceback(traceback) from exc_value
  File "C:\Users\pk\anaconda3\envs\django\Lib\site-packages\django\db\backends\utils.py", line 105, in _execute
    return self.cursor.execute(sql, params)
           ^^^^^^^^^^^^^^^^^^^^^^^^^^^^^^^^
  File "C:\Users\pk\anaconda3\envs\django\Lib\site-packages\django\db\backends\sqlite3\base.py", line 328, in execute
    return super().execute(query, params)
           ^^^^^^^^^^^^^^^^^^^^^^^^^^^^^^
django.db.utils.IntegrityError: NOT NULL constraint failed: myapp_product.date_added
ERROR 2024-01-29 21:05:36,198 basehttp 1108 29644 "POST /create_product/ HTTP/1.1" 500 172007
INFO 2024-01-29 21:13:48,968 autoreload 1108 29940 H:\web\django\lesson_1\myapp\models.py changed, reloading.
INFO 2024-01-29 21:13:49,965 autoreload 32968 30796 Watching for file changes with StatReloader
INFO 2024-01-29 21:15:22,632 autoreload 33064 14744 Watching for file changes with StatReloader
INFO 2024-01-29 21:15:31,893 basehttp 33064 4828 "POST /create_product/ HTTP/1.1" 302 0
INFO 2024-01-29 21:15:31,938 basehttp 33064 4828 "GET / HTTP/1.1" 200 924
WARNING 2024-01-29 21:15:32,068 log 33064 4828 Not Found: /favicon.ico
INFO 2024-01-29 21:15:32,068 basehttp 33064 4828 - Broken pipe from ('127.0.0.1', 54875)
INFO 2024-01-29 21:15:37,205 basehttp 33064 26184 "GET /create_customer/ HTTP/1.1" 200 1187
INFO 2024-01-29 21:15:52,428 basehttp 33064 26184 "POST /create_customer/ HTTP/1.1" 302 0
INFO 2024-01-29 21:15:52,443 basehttp 33064 26184 "GET / HTTP/1.1" 200 1103
INFO 2024-02-01 16:24:17,815 autoreload 25824 24024 Watching for file changes with StatReloader
ERROR 2024-02-01 16:24:56,453 log 25824 26716 Internal Server Error: /product_list/42/week/
Traceback (most recent call last):
  File "C:\Users\pk\anaconda3\envs\django\Lib\site-packages\django\db\models\fields\__init__.py", line 2112, in get_prep_value
    return int(value)
           ^^^^^^^^^^
TypeError: int() argument must be a string, a bytes-like object or a real number, not 'builtin_function_or_method'

The above exception was the direct cause of the following exception:

Traceback (most recent call last):
  File "C:\Users\pk\anaconda3\envs\django\Lib\site-packages\django\core\handlers\exception.py", line 55, in inner
    response = get_response(request)
               ^^^^^^^^^^^^^^^^^^^^^
  File "C:\Users\pk\anaconda3\envs\django\Lib\site-packages\django\core\handlers\base.py", line 197, in _get_response
    response = wrapped_callback(request, *callback_args, **callback_kwargs)
               ^^^^^^^^^^^^^^^^^^^^^^^^^^^^^^^^^^^^^^^^^^^^^^^^^^^^^^^^^^^^
  File "H:\web\django\lesson_1\myapp\views.py", line 123, in product_list
    cur_customer = Customer.objects.get(pk=id)
                   ^^^^^^^^^^^^^^^^^^^^^^^^^^^
  File "C:\Users\pk\anaconda3\envs\django\Lib\site-packages\django\db\models\manager.py", line 87, in manager_method
    return getattr(self.get_queryset(), name)(*args, **kwargs)
           ^^^^^^^^^^^^^^^^^^^^^^^^^^^^^^^^^^^^^^^^^^^^^^^^^^^
  File "C:\Users\pk\anaconda3\envs\django\Lib\site-packages\django\db\models\query.py", line 633, in get
    clone = self._chain() if self.query.combinator else self.filter(*args, **kwargs)
                                                        ^^^^^^^^^^^^^^^^^^^^^^^^^^^^
  File "C:\Users\pk\anaconda3\envs\django\Lib\site-packages\django\db\models\query.py", line 1476, in filter
    return self._filter_or_exclude(False, args, kwargs)
           ^^^^^^^^^^^^^^^^^^^^^^^^^^^^^^^^^^^^^^^^^^^^
  File "C:\Users\pk\anaconda3\envs\django\Lib\site-packages\django\db\models\query.py", line 1494, in _filter_or_exclude
    clone._filter_or_exclude_inplace(negate, args, kwargs)
  File "C:\Users\pk\anaconda3\envs\django\Lib\site-packages\django\db\models\query.py", line 1501, in _filter_or_exclude_inplace
    self._query.add_q(Q(*args, **kwargs))
  File "C:\Users\pk\anaconda3\envs\django\Lib\site-packages\django\db\models\sql\query.py", line 1602, in add_q
    clause, _ = self._add_q(q_object, self.used_aliases)
                ^^^^^^^^^^^^^^^^^^^^^^^^^^^^^^^^^^^^^^^^
  File "C:\Users\pk\anaconda3\envs\django\Lib\site-packages\django\db\models\sql\query.py", line 1634, in _add_q
    child_clause, needed_inner = self.build_filter(
                                 ^^^^^^^^^^^^^^^^^^
  File "C:\Users\pk\anaconda3\envs\django\Lib\site-packages\django\db\models\sql\query.py", line 1548, in build_filter
    condition = self.build_lookup(lookups, col, value)
                ^^^^^^^^^^^^^^^^^^^^^^^^^^^^^^^^^^^^^^
  File "C:\Users\pk\anaconda3\envs\django\Lib\site-packages\django\db\models\sql\query.py", line 1378, in build_lookup
    lookup = lookup_class(lhs, rhs)
             ^^^^^^^^^^^^^^^^^^^^^^
  File "C:\Users\pk\anaconda3\envs\django\Lib\site-packages\django\db\models\lookups.py", line 30, in __init__
    self.rhs = self.get_prep_lookup()
               ^^^^^^^^^^^^^^^^^^^^^^
  File "C:\Users\pk\anaconda3\envs\django\Lib\site-packages\django\db\models\lookups.py", line 362, in get_prep_lookup
    return super().get_prep_lookup()
           ^^^^^^^^^^^^^^^^^^^^^^^^^
  File "C:\Users\pk\anaconda3\envs\django\Lib\site-packages\django\db\models\lookups.py", line 88, in get_prep_lookup
    return self.lhs.output_field.get_prep_value(self.rhs)
           ^^^^^^^^^^^^^^^^^^^^^^^^^^^^^^^^^^^^^^^^^^^^^^
  File "C:\Users\pk\anaconda3\envs\django\Lib\site-packages\django\db\models\fields\__init__.py", line 2114, in get_prep_value
    raise e.__class__(
TypeError: Field 'id' expected a number but got <built-in function id>.
ERROR 2024-02-01 16:24:56,465 basehttp 25824 26716 "GET /product_list/42/week/ HTTP/1.1" 500 135769
WARNING 2024-02-01 16:24:56,830 log 25824 26716 Not Found: /favicon.ico
WARNING 2024-02-01 16:24:56,831 basehttp 25824 26716 "GET /favicon.ico HTTP/1.1" 404 4303
INFO 2024-02-01 16:31:07,679 autoreload 25824 24024 H:\web\django\lesson_1\myapp\views.py changed, reloading.
INFO 2024-02-01 16:31:08,709 autoreload 17044 16368 Watching for file changes with StatReloader
INFO 2024-02-01 16:31:09,204 basehttp 17044 27052 "GET /product_list/42/week/ HTTP/1.1" 200 91
INFO 2024-02-01 16:31:43,294 autoreload 17044 16368 H:\web\django\lesson_1\myapp\views.py changed, reloading.
INFO 2024-02-01 16:31:44,327 autoreload 27368 26024 Watching for file changes with StatReloader
INFO 2024-02-01 16:33:13,517 basehttp 27368 4948 "GET /product_list/42/week/ HTTP/1.1" 200 174
INFO 2024-02-01 16:33:29,659 basehttp 27368 4948 "GET /product_list/43/week/ HTTP/1.1" 200 174
INFO 2024-02-01 16:33:41,149 basehttp 27368 4948 "GET /product_list/43/year/ HTTP/1.1" 200 990
INFO 2024-02-01 16:35:22,042 basehttp 27368 4948 "GET /product_list/43/year/ HTTP/1.1" 200 1129
INFO 2024-02-01 16:35:33,825 basehttp 27368 4948 "GET /product_list/43/month/ HTTP/1.1" 200 170
INFO 2024-02-01 16:35:43,286 basehttp 27368 4948 "GET /product_list/42/month/ HTTP/1.1" 200 170
INFO 2024-02-01 16:35:51,961 basehttp 27368 4948 "GET /product_list/44/month/ HTTP/1.1" 200 713
INFO 2024-02-01 16:36:47,408 basehttp 27368 4948 "GET /product_list/44/month/ HTTP/1.1" 200 746
INFO 2024-02-01 16:37:10,955 basehttp 27368 4948 "GET /product_list/44/month/ HTTP/1.1" 200 746
INFO 2024-02-01 16:37:57,618 autoreload 27368 26024 H:\web\django\lesson_1\myapp\views.py changed, reloading.
INFO 2024-02-01 16:37:58,669 autoreload 27004 13100 Watching for file changes with StatReloader
INFO 2024-02-01 16:38:54,938 basehttp 27004 24848 "GET /product_list/44/month/ HTTP/1.1" 200 804
INFO 2024-02-01 16:39:01,701 basehttp 27004 24848 "GET /product_list/44/month/ HTTP/1.1" 200 805
INFO 2024-02-01 16:39:12,007 basehttp 27004 24848 "GET /product_list/44/month/ HTTP/1.1" 200 810
INFO 2024-02-01 16:39:12,934 basehttp 27004 24848 "GET /product_list/44/month/ HTTP/1.1" 200 810
INFO 2024-02-01 16:39:20,914 basehttp 27004 24848 "GET /product_list/44/month/ HTTP/1.1" 200 814
INFO 2024-02-01 16:46:43,703 autoreload 27004 13100 H:\web\django\lesson_1\myapp\views.py changed, reloading.
INFO 2024-02-01 16:46:44,752 autoreload 28248 30252 Watching for file changes with StatReloader
INFO 2024-02-05 18:30:38,283 autoreload 10124 27844 Watching for file changes with StatReloader
ERROR 2024-02-05 18:31:29,107 log 10124 34256 Internal Server Error: /product/4/form_image/
Traceback (most recent call last):
  File "C:\Users\pk\anaconda3\envs\django\Lib\site-packages\django\core\handlers\exception.py", line 55, in inner
    response = get_response(request)
               ^^^^^^^^^^^^^^^^^^^^^
  File "C:\Users\pk\anaconda3\envs\django\Lib\site-packages\django\core\handlers\base.py", line 197, in _get_response
    response = wrapped_callback(request, *callback_args, **callback_kwargs)
               ^^^^^^^^^^^^^^^^^^^^^^^^^^^^^^^^^^^^^^^^^^^^^^^^^^^^^^^^^^^^
TypeError: product_add_image() missing 1 required positional argument: 'period'
INFO 2024-02-05 18:31:40,911 autoreload 10124 27844 H:\web\django\lesson_1\myapp\views.py changed, reloading.
ERROR 2024-02-05 18:32:02,822 log 10124 12376 Internal Server Error: /
Traceback (most recent call last):
  File "C:\Users\pk\anaconda3\envs\django\Lib\site-packages\django\core\handlers\exception.py", line 55, in inner
    response = get_response(request)
               ^^^^^^^^^^^^^^^^^^^^^
  File "C:\Users\pk\anaconda3\envs\django\Lib\site-packages\django\core\handlers\base.py", line 197, in _get_response
    response = wrapped_callback(request, *callback_args, **callback_kwargs)
               ^^^^^^^^^^^^^^^^^^^^^^^^^^^^^^^^^^^^^^^^^^^^^^^^^^^^^^^^^^^^
  File "H:\web\django\lesson_1\myapp\views.py", line 64, in homepage
    return render(request, 'homepage.html', context)
           ^^^^^^^^^^^^^^^^^^^^^^^^^^^^^^^^^^^^^^^^^
  File "C:\Users\pk\anaconda3\envs\django\Lib\site-packages\django\shortcuts.py", line 24, in render
    content = loader.render_to_string(template_name, context, request, using=using)
              ^^^^^^^^^^^^^^^^^^^^^^^^^^^^^^^^^^^^^^^^^^^^^^^^^^^^^^^^^^^^^^^^^^^^^
  File "C:\Users\pk\anaconda3\envs\django\Lib\site-packages\django\template\loader.py", line 62, in render_to_string
    return template.render(context, request)
           ^^^^^^^^^^^^^^^^^^^^^^^^^^^^^^^^^
  File "C:\Users\pk\anaconda3\envs\django\Lib\site-packages\django\template\backends\django.py", line 61, in render
    return self.template.render(context)
           ^^^^^^^^^^^^^^^^^^^^^^^^^^^^^
  File "C:\Users\pk\anaconda3\envs\django\Lib\site-packages\django\template\base.py", line 171, in render
    return self._render(context)
           ^^^^^^^^^^^^^^^^^^^^^
  File "C:\Users\pk\anaconda3\envs\django\Lib\site-packages\django\template\base.py", line 163, in _render
    return self.nodelist.render(context)
           ^^^^^^^^^^^^^^^^^^^^^^^^^^^^^
  File "C:\Users\pk\anaconda3\envs\django\Lib\site-packages\django\template\base.py", line 1000, in render
    return SafeString("".join([node.render_annotated(context) for node in self]))
                               ^^^^^^^^^^^^^^^^^^^^^^^^^^^^^^
  File "C:\Users\pk\anaconda3\envs\django\Lib\site-packages\django\template\base.py", line 961, in render_annotated
    return self.render(context)
           ^^^^^^^^^^^^^^^^^^^^
  File "C:\Users\pk\anaconda3\envs\django\Lib\site-packages\django\template\loader_tags.py", line 159, in render
    return compiled_parent._render(context)
           ^^^^^^^^^^^^^^^^^^^^^^^^^^^^^^^^
  File "C:\Users\pk\anaconda3\envs\django\Lib\site-packages\django\template\base.py", line 163, in _render
    return self.nodelist.render(context)
           ^^^^^^^^^^^^^^^^^^^^^^^^^^^^^
  File "C:\Users\pk\anaconda3\envs\django\Lib\site-packages\django\template\base.py", line 1000, in render
    return SafeString("".join([node.render_annotated(context) for node in self]))
                               ^^^^^^^^^^^^^^^^^^^^^^^^^^^^^^
  File "C:\Users\pk\anaconda3\envs\django\Lib\site-packages\django\template\base.py", line 961, in render_annotated
    return self.render(context)
           ^^^^^^^^^^^^^^^^^^^^
  File "C:\Users\pk\anaconda3\envs\django\Lib\site-packages\django\template\loader_tags.py", line 65, in render
    result = block.nodelist.render(context)
             ^^^^^^^^^^^^^^^^^^^^^^^^^^^^^^
  File "C:\Users\pk\anaconda3\envs\django\Lib\site-packages\django\template\base.py", line 1000, in render
    return SafeString("".join([node.render_annotated(context) for node in self]))
                               ^^^^^^^^^^^^^^^^^^^^^^^^^^^^^^
  File "C:\Users\pk\anaconda3\envs\django\Lib\site-packages\django\template\base.py", line 961, in render_annotated
    return self.render(context)
           ^^^^^^^^^^^^^^^^^^^^
  File "C:\Users\pk\anaconda3\envs\django\Lib\site-packages\django\template\defaulttags.py", line 325, in render
    return nodelist.render(context)
           ^^^^^^^^^^^^^^^^^^^^^^^^
  File "C:\Users\pk\anaconda3\envs\django\Lib\site-packages\django\template\base.py", line 1000, in render
    return SafeString("".join([node.render_annotated(context) for node in self]))
                               ^^^^^^^^^^^^^^^^^^^^^^^^^^^^^^
  File "C:\Users\pk\anaconda3\envs\django\Lib\site-packages\django\template\base.py", line 961, in render_annotated
    return self.render(context)
           ^^^^^^^^^^^^^^^^^^^^
  File "C:\Users\pk\anaconda3\envs\django\Lib\site-packages\django\template\defaulttags.py", line 241, in render
    nodelist.append(node.render_annotated(context))
                    ^^^^^^^^^^^^^^^^^^^^^^^^^^^^^^
  File "C:\Users\pk\anaconda3\envs\django\Lib\site-packages\django\template\base.py", line 961, in render_annotated
    return self.render(context)
           ^^^^^^^^^^^^^^^^^^^^
  File "C:\Users\pk\anaconda3\envs\django\Lib\site-packages\django\template\defaulttags.py", line 478, in render
    url = reverse(view_name, args=args, kwargs=kwargs, current_app=current_app)
          ^^^^^^^^^^^^^^^^^^^^^^^^^^^^^^^^^^^^^^^^^^^^^^^^^^^^^^^^^^^^^^^^^^^^^
  File "C:\Users\pk\anaconda3\envs\django\Lib\site-packages\django\urls\base.py", line 88, in reverse
    return resolver._reverse_with_prefix(view, prefix, *args, **kwargs)
           ^^^^^^^^^^^^^^^^^^^^^^^^^^^^^^^^^^^^^^^^^^^^^^^^^^^^^^^^^^^^
  File "C:\Users\pk\anaconda3\envs\django\Lib\site-packages\django\urls\resolvers.py", line 848, in _reverse_with_prefix
    raise NoReverseMatch(msg)
django.urls.exceptions.NoReverseMatch: Reverse for 'update_order' not found. 'update_order' is not a valid view function or pattern name.
INFO 2024-02-05 18:32:14,194 basehttp 10124 34256 - Broken pipe from ('127.0.0.1', 55399)
INFO 2024-02-05 18:32:15,245 autoreload 33232 1116 Watching for file changes with StatReloader
ERROR 2024-02-05 18:32:15,766 log 33232 34096 Internal Server Error: /
Traceback (most recent call last):
  File "C:\Users\pk\anaconda3\envs\django\Lib\site-packages\django\core\handlers\exception.py", line 55, in inner
    response = get_response(request)
               ^^^^^^^^^^^^^^^^^^^^^
  File "C:\Users\pk\anaconda3\envs\django\Lib\site-packages\django\core\handlers\base.py", line 197, in _get_response
    response = wrapped_callback(request, *callback_args, **callback_kwargs)
               ^^^^^^^^^^^^^^^^^^^^^^^^^^^^^^^^^^^^^^^^^^^^^^^^^^^^^^^^^^^^
  File "H:\web\django\lesson_1\myapp\views.py", line 64, in homepage
    return render(request, 'homepage.html', context)
           ^^^^^^^^^^^^^^^^^^^^^^^^^^^^^^^^^^^^^^^^^
  File "C:\Users\pk\anaconda3\envs\django\Lib\site-packages\django\shortcuts.py", line 24, in render
    content = loader.render_to_string(template_name, context, request, using=using)
              ^^^^^^^^^^^^^^^^^^^^^^^^^^^^^^^^^^^^^^^^^^^^^^^^^^^^^^^^^^^^^^^^^^^^^
  File "C:\Users\pk\anaconda3\envs\django\Lib\site-packages\django\template\loader.py", line 62, in render_to_string
    return template.render(context, request)
           ^^^^^^^^^^^^^^^^^^^^^^^^^^^^^^^^^
  File "C:\Users\pk\anaconda3\envs\django\Lib\site-packages\django\template\backends\django.py", line 61, in render
    return self.template.render(context)
           ^^^^^^^^^^^^^^^^^^^^^^^^^^^^^
  File "C:\Users\pk\anaconda3\envs\django\Lib\site-packages\django\template\base.py", line 171, in render
    return self._render(context)
           ^^^^^^^^^^^^^^^^^^^^^
  File "C:\Users\pk\anaconda3\envs\django\Lib\site-packages\django\template\base.py", line 163, in _render
    return self.nodelist.render(context)
           ^^^^^^^^^^^^^^^^^^^^^^^^^^^^^
  File "C:\Users\pk\anaconda3\envs\django\Lib\site-packages\django\template\base.py", line 1000, in render
    return SafeString("".join([node.render_annotated(context) for node in self]))
                               ^^^^^^^^^^^^^^^^^^^^^^^^^^^^^^
  File "C:\Users\pk\anaconda3\envs\django\Lib\site-packages\django\template\base.py", line 961, in render_annotated
    return self.render(context)
           ^^^^^^^^^^^^^^^^^^^^
  File "C:\Users\pk\anaconda3\envs\django\Lib\site-packages\django\template\loader_tags.py", line 159, in render
    return compiled_parent._render(context)
           ^^^^^^^^^^^^^^^^^^^^^^^^^^^^^^^^
  File "C:\Users\pk\anaconda3\envs\django\Lib\site-packages\django\template\base.py", line 163, in _render
    return self.nodelist.render(context)
           ^^^^^^^^^^^^^^^^^^^^^^^^^^^^^
  File "C:\Users\pk\anaconda3\envs\django\Lib\site-packages\django\template\base.py", line 1000, in render
    return SafeString("".join([node.render_annotated(context) for node in self]))
                               ^^^^^^^^^^^^^^^^^^^^^^^^^^^^^^
  File "C:\Users\pk\anaconda3\envs\django\Lib\site-packages\django\template\base.py", line 961, in render_annotated
    return self.render(context)
           ^^^^^^^^^^^^^^^^^^^^
  File "C:\Users\pk\anaconda3\envs\django\Lib\site-packages\django\template\loader_tags.py", line 65, in render
    result = block.nodelist.render(context)
             ^^^^^^^^^^^^^^^^^^^^^^^^^^^^^^
  File "C:\Users\pk\anaconda3\envs\django\Lib\site-packages\django\template\base.py", line 1000, in render
    return SafeString("".join([node.render_annotated(context) for node in self]))
                               ^^^^^^^^^^^^^^^^^^^^^^^^^^^^^^
  File "C:\Users\pk\anaconda3\envs\django\Lib\site-packages\django\template\base.py", line 961, in render_annotated
    return self.render(context)
           ^^^^^^^^^^^^^^^^^^^^
  File "C:\Users\pk\anaconda3\envs\django\Lib\site-packages\django\template\defaulttags.py", line 325, in render
    return nodelist.render(context)
           ^^^^^^^^^^^^^^^^^^^^^^^^
  File "C:\Users\pk\anaconda3\envs\django\Lib\site-packages\django\template\base.py", line 1000, in render
    return SafeString("".join([node.render_annotated(context) for node in self]))
                               ^^^^^^^^^^^^^^^^^^^^^^^^^^^^^^
  File "C:\Users\pk\anaconda3\envs\django\Lib\site-packages\django\template\base.py", line 961, in render_annotated
    return self.render(context)
           ^^^^^^^^^^^^^^^^^^^^
  File "C:\Users\pk\anaconda3\envs\django\Lib\site-packages\django\template\defaulttags.py", line 241, in render
    nodelist.append(node.render_annotated(context))
                    ^^^^^^^^^^^^^^^^^^^^^^^^^^^^^^
  File "C:\Users\pk\anaconda3\envs\django\Lib\site-packages\django\template\base.py", line 961, in render_annotated
    return self.render(context)
           ^^^^^^^^^^^^^^^^^^^^
  File "C:\Users\pk\anaconda3\envs\django\Lib\site-packages\django\template\defaulttags.py", line 478, in render
    url = reverse(view_name, args=args, kwargs=kwargs, current_app=current_app)
          ^^^^^^^^^^^^^^^^^^^^^^^^^^^^^^^^^^^^^^^^^^^^^^^^^^^^^^^^^^^^^^^^^^^^^
  File "C:\Users\pk\anaconda3\envs\django\Lib\site-packages\django\urls\base.py", line 88, in reverse
    return resolver._reverse_with_prefix(view, prefix, *args, **kwargs)
           ^^^^^^^^^^^^^^^^^^^^^^^^^^^^^^^^^^^^^^^^^^^^^^^^^^^^^^^^^^^^
  File "C:\Users\pk\anaconda3\envs\django\Lib\site-packages\django\urls\resolvers.py", line 848, in _reverse_with_prefix
    raise NoReverseMatch(msg)
django.urls.exceptions.NoReverseMatch: Reverse for 'update_order' not found. 'update_order' is not a valid view function or pattern name.
ERROR 2024-02-05 18:32:15,786 basehttp 33232 34096 "GET / HTTP/1.1" 500 215299
WARNING 2024-02-05 18:32:16,246 log 33232 34096 Not Found: /favicon.ico
WARNING 2024-02-05 18:32:16,248 basehttp 33232 34096 "GET /favicon.ico HTTP/1.1" 404 4518
ERROR 2024-02-05 18:32:46,034 log 33232 34096 Internal Server Error: /
Traceback (most recent call last):
  File "C:\Users\pk\anaconda3\envs\django\Lib\site-packages\django\core\handlers\exception.py", line 55, in inner
    response = get_response(request)
               ^^^^^^^^^^^^^^^^^^^^^
  File "C:\Users\pk\anaconda3\envs\django\Lib\site-packages\django\core\handlers\base.py", line 197, in _get_response
    response = wrapped_callback(request, *callback_args, **callback_kwargs)
               ^^^^^^^^^^^^^^^^^^^^^^^^^^^^^^^^^^^^^^^^^^^^^^^^^^^^^^^^^^^^
  File "H:\web\django\lesson_1\myapp\views.py", line 64, in homepage
    return render(request, 'homepage.html', context)
           ^^^^^^^^^^^^^^^^^^^^^^^^^^^^^^^^^^^^^^^^^
  File "C:\Users\pk\anaconda3\envs\django\Lib\site-packages\django\shortcuts.py", line 24, in render
    content = loader.render_to_string(template_name, context, request, using=using)
              ^^^^^^^^^^^^^^^^^^^^^^^^^^^^^^^^^^^^^^^^^^^^^^^^^^^^^^^^^^^^^^^^^^^^^
  File "C:\Users\pk\anaconda3\envs\django\Lib\site-packages\django\template\loader.py", line 62, in render_to_string
    return template.render(context, request)
           ^^^^^^^^^^^^^^^^^^^^^^^^^^^^^^^^^
  File "C:\Users\pk\anaconda3\envs\django\Lib\site-packages\django\template\backends\django.py", line 61, in render
    return self.template.render(context)
           ^^^^^^^^^^^^^^^^^^^^^^^^^^^^^
  File "C:\Users\pk\anaconda3\envs\django\Lib\site-packages\django\template\base.py", line 171, in render
    return self._render(context)
           ^^^^^^^^^^^^^^^^^^^^^
  File "C:\Users\pk\anaconda3\envs\django\Lib\site-packages\django\template\base.py", line 163, in _render
    return self.nodelist.render(context)
           ^^^^^^^^^^^^^^^^^^^^^^^^^^^^^
  File "C:\Users\pk\anaconda3\envs\django\Lib\site-packages\django\template\base.py", line 1000, in render
    return SafeString("".join([node.render_annotated(context) for node in self]))
                               ^^^^^^^^^^^^^^^^^^^^^^^^^^^^^^
  File "C:\Users\pk\anaconda3\envs\django\Lib\site-packages\django\template\base.py", line 961, in render_annotated
    return self.render(context)
           ^^^^^^^^^^^^^^^^^^^^
  File "C:\Users\pk\anaconda3\envs\django\Lib\site-packages\django\template\loader_tags.py", line 159, in render
    return compiled_parent._render(context)
           ^^^^^^^^^^^^^^^^^^^^^^^^^^^^^^^^
  File "C:\Users\pk\anaconda3\envs\django\Lib\site-packages\django\template\base.py", line 163, in _render
    return self.nodelist.render(context)
           ^^^^^^^^^^^^^^^^^^^^^^^^^^^^^
  File "C:\Users\pk\anaconda3\envs\django\Lib\site-packages\django\template\base.py", line 1000, in render
    return SafeString("".join([node.render_annotated(context) for node in self]))
                               ^^^^^^^^^^^^^^^^^^^^^^^^^^^^^^
  File "C:\Users\pk\anaconda3\envs\django\Lib\site-packages\django\template\base.py", line 961, in render_annotated
    return self.render(context)
           ^^^^^^^^^^^^^^^^^^^^
  File "C:\Users\pk\anaconda3\envs\django\Lib\site-packages\django\template\loader_tags.py", line 65, in render
    result = block.nodelist.render(context)
             ^^^^^^^^^^^^^^^^^^^^^^^^^^^^^^
  File "C:\Users\pk\anaconda3\envs\django\Lib\site-packages\django\template\base.py", line 1000, in render
    return SafeString("".join([node.render_annotated(context) for node in self]))
                               ^^^^^^^^^^^^^^^^^^^^^^^^^^^^^^
  File "C:\Users\pk\anaconda3\envs\django\Lib\site-packages\django\template\base.py", line 961, in render_annotated
    return self.render(context)
           ^^^^^^^^^^^^^^^^^^^^
  File "C:\Users\pk\anaconda3\envs\django\Lib\site-packages\django\template\defaulttags.py", line 325, in render
    return nodelist.render(context)
           ^^^^^^^^^^^^^^^^^^^^^^^^
  File "C:\Users\pk\anaconda3\envs\django\Lib\site-packages\django\template\base.py", line 1000, in render
    return SafeString("".join([node.render_annotated(context) for node in self]))
                               ^^^^^^^^^^^^^^^^^^^^^^^^^^^^^^
  File "C:\Users\pk\anaconda3\envs\django\Lib\site-packages\django\template\base.py", line 961, in render_annotated
    return self.render(context)
           ^^^^^^^^^^^^^^^^^^^^
  File "C:\Users\pk\anaconda3\envs\django\Lib\site-packages\django\template\defaulttags.py", line 241, in render
    nodelist.append(node.render_annotated(context))
                    ^^^^^^^^^^^^^^^^^^^^^^^^^^^^^^
  File "C:\Users\pk\anaconda3\envs\django\Lib\site-packages\django\template\base.py", line 961, in render_annotated
    return self.render(context)
           ^^^^^^^^^^^^^^^^^^^^
  File "C:\Users\pk\anaconda3\envs\django\Lib\site-packages\django\template\defaulttags.py", line 478, in render
    url = reverse(view_name, args=args, kwargs=kwargs, current_app=current_app)
          ^^^^^^^^^^^^^^^^^^^^^^^^^^^^^^^^^^^^^^^^^^^^^^^^^^^^^^^^^^^^^^^^^^^^^
  File "C:\Users\pk\anaconda3\envs\django\Lib\site-packages\django\urls\base.py", line 88, in reverse
    return resolver._reverse_with_prefix(view, prefix, *args, **kwargs)
           ^^^^^^^^^^^^^^^^^^^^^^^^^^^^^^^^^^^^^^^^^^^^^^^^^^^^^^^^^^^^
  File "C:\Users\pk\anaconda3\envs\django\Lib\site-packages\django\urls\resolvers.py", line 848, in _reverse_with_prefix
    raise NoReverseMatch(msg)
django.urls.exceptions.NoReverseMatch: Reverse for 'update_order' not found. 'update_order' is not a valid view function or pattern name.
ERROR 2024-02-05 18:32:46,043 basehttp 33232 34096 "GET / HTTP/1.1" 500 215436
ERROR 2024-02-05 18:32:57,842 log 33232 34096 Internal Server Error: /
Traceback (most recent call last):
  File "C:\Users\pk\anaconda3\envs\django\Lib\site-packages\django\core\handlers\exception.py", line 55, in inner
    response = get_response(request)
               ^^^^^^^^^^^^^^^^^^^^^
  File "C:\Users\pk\anaconda3\envs\django\Lib\site-packages\django\core\handlers\base.py", line 197, in _get_response
    response = wrapped_callback(request, *callback_args, **callback_kwargs)
               ^^^^^^^^^^^^^^^^^^^^^^^^^^^^^^^^^^^^^^^^^^^^^^^^^^^^^^^^^^^^
  File "H:\web\django\lesson_1\myapp\views.py", line 64, in homepage
    return render(request, 'homepage.html', context)
           ^^^^^^^^^^^^^^^^^^^^^^^^^^^^^^^^^^^^^^^^^
  File "C:\Users\pk\anaconda3\envs\django\Lib\site-packages\django\shortcuts.py", line 24, in render
    content = loader.render_to_string(template_name, context, request, using=using)
              ^^^^^^^^^^^^^^^^^^^^^^^^^^^^^^^^^^^^^^^^^^^^^^^^^^^^^^^^^^^^^^^^^^^^^
  File "C:\Users\pk\anaconda3\envs\django\Lib\site-packages\django\template\loader.py", line 62, in render_to_string
    return template.render(context, request)
           ^^^^^^^^^^^^^^^^^^^^^^^^^^^^^^^^^
  File "C:\Users\pk\anaconda3\envs\django\Lib\site-packages\django\template\backends\django.py", line 61, in render
    return self.template.render(context)
           ^^^^^^^^^^^^^^^^^^^^^^^^^^^^^
  File "C:\Users\pk\anaconda3\envs\django\Lib\site-packages\django\template\base.py", line 171, in render
    return self._render(context)
           ^^^^^^^^^^^^^^^^^^^^^
  File "C:\Users\pk\anaconda3\envs\django\Lib\site-packages\django\template\base.py", line 163, in _render
    return self.nodelist.render(context)
           ^^^^^^^^^^^^^^^^^^^^^^^^^^^^^
  File "C:\Users\pk\anaconda3\envs\django\Lib\site-packages\django\template\base.py", line 1000, in render
    return SafeString("".join([node.render_annotated(context) for node in self]))
                               ^^^^^^^^^^^^^^^^^^^^^^^^^^^^^^
  File "C:\Users\pk\anaconda3\envs\django\Lib\site-packages\django\template\base.py", line 961, in render_annotated
    return self.render(context)
           ^^^^^^^^^^^^^^^^^^^^
  File "C:\Users\pk\anaconda3\envs\django\Lib\site-packages\django\template\loader_tags.py", line 159, in render
    return compiled_parent._render(context)
           ^^^^^^^^^^^^^^^^^^^^^^^^^^^^^^^^
  File "C:\Users\pk\anaconda3\envs\django\Lib\site-packages\django\template\base.py", line 163, in _render
    return self.nodelist.render(context)
           ^^^^^^^^^^^^^^^^^^^^^^^^^^^^^
  File "C:\Users\pk\anaconda3\envs\django\Lib\site-packages\django\template\base.py", line 1000, in render
    return SafeString("".join([node.render_annotated(context) for node in self]))
                               ^^^^^^^^^^^^^^^^^^^^^^^^^^^^^^
  File "C:\Users\pk\anaconda3\envs\django\Lib\site-packages\django\template\base.py", line 961, in render_annotated
    return self.render(context)
           ^^^^^^^^^^^^^^^^^^^^
  File "C:\Users\pk\anaconda3\envs\django\Lib\site-packages\django\template\loader_tags.py", line 65, in render
    result = block.nodelist.render(context)
             ^^^^^^^^^^^^^^^^^^^^^^^^^^^^^^
  File "C:\Users\pk\anaconda3\envs\django\Lib\site-packages\django\template\base.py", line 1000, in render
    return SafeString("".join([node.render_annotated(context) for node in self]))
                               ^^^^^^^^^^^^^^^^^^^^^^^^^^^^^^
  File "C:\Users\pk\anaconda3\envs\django\Lib\site-packages\django\template\base.py", line 961, in render_annotated
    return self.render(context)
           ^^^^^^^^^^^^^^^^^^^^
  File "C:\Users\pk\anaconda3\envs\django\Lib\site-packages\django\template\defaulttags.py", line 325, in render
    return nodelist.render(context)
           ^^^^^^^^^^^^^^^^^^^^^^^^
  File "C:\Users\pk\anaconda3\envs\django\Lib\site-packages\django\template\base.py", line 1000, in render
    return SafeString("".join([node.render_annotated(context) for node in self]))
                               ^^^^^^^^^^^^^^^^^^^^^^^^^^^^^^
  File "C:\Users\pk\anaconda3\envs\django\Lib\site-packages\django\template\base.py", line 961, in render_annotated
    return self.render(context)
           ^^^^^^^^^^^^^^^^^^^^
  File "C:\Users\pk\anaconda3\envs\django\Lib\site-packages\django\template\defaulttags.py", line 241, in render
    nodelist.append(node.render_annotated(context))
                    ^^^^^^^^^^^^^^^^^^^^^^^^^^^^^^
  File "C:\Users\pk\anaconda3\envs\django\Lib\site-packages\django\template\base.py", line 961, in render_annotated
    return self.render(context)
           ^^^^^^^^^^^^^^^^^^^^
  File "C:\Users\pk\anaconda3\envs\django\Lib\site-packages\django\template\defaulttags.py", line 478, in render
    url = reverse(view_name, args=args, kwargs=kwargs, current_app=current_app)
          ^^^^^^^^^^^^^^^^^^^^^^^^^^^^^^^^^^^^^^^^^^^^^^^^^^^^^^^^^^^^^^^^^^^^^
  File "C:\Users\pk\anaconda3\envs\django\Lib\site-packages\django\urls\base.py", line 88, in reverse
    return resolver._reverse_with_prefix(view, prefix, *args, **kwargs)
           ^^^^^^^^^^^^^^^^^^^^^^^^^^^^^^^^^^^^^^^^^^^^^^^^^^^^^^^^^^^^
  File "C:\Users\pk\anaconda3\envs\django\Lib\site-packages\django\urls\resolvers.py", line 848, in _reverse_with_prefix
    raise NoReverseMatch(msg)
django.urls.exceptions.NoReverseMatch: Reverse for 'update_order' not found. 'update_order' is not a valid view function or pattern name.
ERROR 2024-02-05 18:32:57,848 basehttp 33232 34096 "GET / HTTP/1.1" 500 215436
INFO 2024-02-05 18:33:59,911 autoreload 33232 1116 H:\web\django\lesson_1\myapp\urls.py changed, reloading.
INFO 2024-02-05 18:34:00,973 autoreload 34144 18092 Watching for file changes with StatReloader
INFO 2024-02-05 18:34:12,665 autoreload 34144 18092 H:\web\django\lesson_1\myapp\urls.py changed, reloading.
INFO 2024-02-05 18:34:13,654 autoreload 11448 34068 Watching for file changes with StatReloader
INFO 2024-02-05 18:34:17,554 basehttp 11448 21224 "GET / HTTP/1.1" 200 13166
ERROR 2024-02-05 18:34:46,470 log 11448 21224 Internal Server Error: /product/4/form_image/
Traceback (most recent call last):
  File "C:\Users\pk\anaconda3\envs\django\Lib\site-packages\django\core\handlers\exception.py", line 55, in inner
    response = get_response(request)
               ^^^^^^^^^^^^^^^^^^^^^
  File "C:\Users\pk\anaconda3\envs\django\Lib\site-packages\django\core\handlers\base.py", line 197, in _get_response
    response = wrapped_callback(request, *callback_args, **callback_kwargs)
               ^^^^^^^^^^^^^^^^^^^^^^^^^^^^^^^^^^^^^^^^^^^^^^^^^^^^^^^^^^^^
TypeError: product_add_image() missing 1 required positional argument: 'period'
ERROR 2024-02-05 18:34:46,472 basehttp 11448 21224 "GET /product/4/form_image/ HTTP/1.1" 500 63613
INFO 2024-02-05 18:35:03,972 autoreload 11448 34068 H:\web\django\lesson_1\myapp\views.py changed, reloading.
INFO 2024-02-05 18:35:05,028 autoreload 26936 18640 Watching for file changes with StatReloader
ERROR 2024-02-05 18:35:05,799 log 26936 31788 Internal Server Error: /product/4/form_image/
Traceback (most recent call last):
  File "C:\Users\pk\anaconda3\envs\django\Lib\site-packages\django\core\handlers\exception.py", line 55, in inner
    response = get_response(request)
               ^^^^^^^^^^^^^^^^^^^^^
  File "C:\Users\pk\anaconda3\envs\django\Lib\site-packages\django\core\handlers\base.py", line 197, in _get_response
    response = wrapped_callback(request, *callback_args, **callback_kwargs)
               ^^^^^^^^^^^^^^^^^^^^^^^^^^^^^^^^^^^^^^^^^^^^^^^^^^^^^^^^^^^^
  File "H:\web\django\lesson_1\myapp\views.py", line 152, in product_add_image
    if form.is_valid():
       ^^^^
UnboundLocalError: cannot access local variable 'form' where it is not associated with a value
ERROR 2024-02-05 18:35:05,802 basehttp 26936 31788 "GET /product/4/form_image/ HTTP/1.1" 500 67710
INFO 2024-02-05 18:35:51,635 autoreload 26936 18640 H:\web\django\lesson_1\myapp\views.py changed, reloading.
INFO 2024-02-05 18:35:52,639 autoreload 3584 7416 Watching for file changes with StatReloader
INFO 2024-02-05 18:35:53,017 basehttp 3584 3536 "GET /product/4/form_image/ HTTP/1.1" 200 546
INFO 2024-02-05 18:37:44,306 basehttp 3584 3536 "GET /product/4/form_image/ HTTP/1.1" 200 637
INFO 2024-02-05 18:45:52,758 autoreload 3584 7416 H:\web\django\lesson_1\myapp\forms.py changed, reloading.
INFO 2024-02-05 18:45:53,787 autoreload 23332 27544 Watching for file changes with StatReloader
INFO 2024-02-05 18:46:06,109 autoreload 23332 27544 H:\web\django\lesson_1\myapp\forms.py changed, reloading.
INFO 2024-02-05 18:46:07,147 autoreload 14644 24032 Watching for file changes with StatReloader
INFO 2024-02-05 18:46:09,752 autoreload 14644 24032 H:\web\django\lesson_1\myapp\forms.py changed, reloading.
INFO 2024-02-05 18:46:10,751 autoreload 32336 32328 Watching for file changes with StatReloader
INFO 2024-02-05 18:47:00,797 autoreload 32336 32328 H:\web\django\lesson_1\myapp\forms.py changed, reloading.
INFO 2024-02-05 18:47:01,810 autoreload 9808 20660 Watching for file changes with StatReloader
INFO 2024-02-05 18:51:57,701 autoreload 9808 20660 H:\web\django\lesson_1\myapp\forms.py changed, reloading.
INFO 2024-02-05 18:51:58,726 autoreload 20612 31400 Watching for file changes with StatReloader
INFO 2024-02-05 18:52:03,887 basehttp 20612 27900 "GET /product/4/form_image/ HTTP/1.1" 200 639
INFO 2024-02-05 18:52:05,587 basehttp 20612 27900 "GET /product/4/form_image/ HTTP/1.1" 200 639
INFO 2024-02-05 18:52:52,354 autoreload 20612 31400 H:\web\django\lesson_1\myapp\forms.py changed, reloading.
INFO 2024-02-05 18:52:53,382 autoreload 19360 21500 Watching for file changes with StatReloader
INFO 2024-02-05 18:52:56,468 basehttp 19360 13916 "GET /product/4/form_image/ HTTP/1.1" 200 639
INFO 2024-02-05 18:52:57,262 basehttp 19360 13916 "GET /product/4/form_image/ HTTP/1.1" 200 639
INFO 2024-02-05 18:52:57,479 basehttp 19360 13916 "GET /product/4/form_image/ HTTP/1.1" 200 639
INFO 2024-02-05 18:52:58,724 basehttp 19360 13916 "GET /product/4/form_image/ HTTP/1.1" 200 639
WARNING 2024-02-05 18:52:58,903 log 19360 13916 Not Found: /favicon.ico
WARNING 2024-02-05 18:52:58,904 basehttp 19360 13916 "GET /favicon.ico HTTP/1.1" 404 4539
INFO 2024-02-05 18:53:17,461 basehttp 19360 13916 "GET /product/4/form_image/ HTTP/1.1" 200 639
INFO 2024-02-05 18:53:18,427 basehttp 19360 13916 "GET /product/4/form_image/ HTTP/1.1" 200 639
INFO 2024-02-05 18:53:19,494 basehttp 19360 13916 "GET /product/4/form_image/ HTTP/1.1" 200 639
INFO 2024-02-05 18:54:10,933 autoreload 19360 21500 H:\web\django\lesson_1\myapp\views.py changed, reloading.
INFO 2024-02-05 18:54:11,953 autoreload 20892 22592 Watching for file changes with StatReloader
INFO 2024-02-05 18:54:18,273 autoreload 20892 22592 H:\web\django\lesson_1\myapp\forms.py changed, reloading.
INFO 2024-02-05 18:54:19,296 autoreload 13940 15852 Watching for file changes with StatReloader
INFO 2024-02-05 18:54:24,113 basehttp 13940 20536 "GET /product/4/form_image/ HTTP/1.1" 200 639
INFO 2024-02-05 18:54:25,501 basehttp 13940 20536 "GET /product/4/form_image/ HTTP/1.1" 200 639
INFO 2024-02-05 18:54:29,276 autoreload 13940 15852 H:\web\django\lesson_1\myapp\forms.py changed, reloading.
INFO 2024-02-05 18:54:30,286 autoreload 32548 16352 Watching for file changes with StatReloader
INFO 2024-02-05 18:54:39,926 basehttp 32548 17280 "GET /product/4/form_image/ HTTP/1.1" 200 785
ERROR 2024-02-05 18:55:23,508 log 32548 17280 Internal Server Error: /product/4/form_image/
Traceback (most recent call last):
  File "C:\Users\pk\anaconda3\envs\django\Lib\site-packages\django\core\handlers\exception.py", line 55, in inner
    response = get_response(request)
               ^^^^^^^^^^^^^^^^^^^^^
  File "C:\Users\pk\anaconda3\envs\django\Lib\site-packages\django\core\handlers\base.py", line 204, in _get_response
    self.check_response(response, callback)
  File "C:\Users\pk\anaconda3\envs\django\Lib\site-packages\django\core\handlers\base.py", line 332, in check_response
    raise ValueError(
ValueError: The view myapp.views.product_add_image didn't return an HttpResponse object. It returned None instead.
ERROR 2024-02-05 18:55:23,510 basehttp 32548 17280 "POST /product/4/form_image/ HTTP/1.1" 500 69401
INFO 2024-02-05 19:00:33,489 autoreload 32548 16352 H:\web\django\lesson_1\myapp\views.py changed, reloading.
ERROR 2024-02-05 19:01:07,974 log 32548 8012 Internal Server Error: /product/4/form_image/
Traceback (most recent call last):
  File "C:\Users\pk\anaconda3\envs\django\Lib\site-packages\django\core\handlers\exception.py", line 55, in inner
    response = get_response(request)
               ^^^^^^^^^^^^^^^^^^^^^
  File "C:\Users\pk\anaconda3\envs\django\Lib\site-packages\django\core\handlers\base.py", line 204, in _get_response
    self.check_response(response, callback)
  File "C:\Users\pk\anaconda3\envs\django\Lib\site-packages\django\core\handlers\base.py", line 332, in check_response
    raise ValueError(
ValueError: The view myapp.views.product_add_image didn't return an HttpResponse object. It returned None instead.
INFO 2024-02-05 19:01:39,042 basehttp 32548 32092 "GET /product/4/form_image/ HTTP/1.1" 200 785
ERROR 2024-02-05 19:01:48,678 log 32548 3456 Internal Server Error: /product/4/form_image/
Traceback (most recent call last):
  File "C:\Users\pk\anaconda3\envs\django\Lib\site-packages\django\core\handlers\exception.py", line 55, in inner
    response = get_response(request)
               ^^^^^^^^^^^^^^^^^^^^^
  File "C:\Users\pk\anaconda3\envs\django\Lib\site-packages\django\core\handlers\base.py", line 204, in _get_response
    self.check_response(response, callback)
  File "C:\Users\pk\anaconda3\envs\django\Lib\site-packages\django\core\handlers\base.py", line 332, in check_response
    raise ValueError(
ValueError: The view myapp.views.product_add_image didn't return an HttpResponse object. It returned None instead.
INFO 2024-02-05 19:02:44,451 autoreload 28460 6608 Watching for file changes with StatReloader
ERROR 2024-02-05 19:02:44,868 log 28460 27576 Internal Server Error: /product/4/form_image/
Traceback (most recent call last):
  File "C:\Users\pk\anaconda3\envs\django\Lib\site-packages\django\core\handlers\exception.py", line 55, in inner
    response = get_response(request)
               ^^^^^^^^^^^^^^^^^^^^^
  File "C:\Users\pk\anaconda3\envs\django\Lib\site-packages\django\core\handlers\base.py", line 204, in _get_response
    self.check_response(response, callback)
  File "C:\Users\pk\anaconda3\envs\django\Lib\site-packages\django\core\handlers\base.py", line 332, in check_response
    raise ValueError(
ValueError: The view myapp.views.product_add_image didn't return an HttpResponse object. It returned None instead.
ERROR 2024-02-05 19:02:44,871 basehttp 28460 27576 "POST /product/4/form_image/ HTTP/1.1" 500 69382
INFO 2024-02-05 19:03:50,674 autoreload 2428 12480 Watching for file changes with StatReloader
ERROR 2024-02-05 19:03:52,575 log 2428 28060 Internal Server Error: /product/4/form_image/
Traceback (most recent call last):
  File "C:\Users\pk\anaconda3\envs\django\Lib\site-packages\django\core\handlers\exception.py", line 55, in inner
    response = get_response(request)
               ^^^^^^^^^^^^^^^^^^^^^
  File "C:\Users\pk\anaconda3\envs\django\Lib\site-packages\django\core\handlers\base.py", line 197, in _get_response
    response = wrapped_callback(request, *callback_args, **callback_kwargs)
               ^^^^^^^^^^^^^^^^^^^^^^^^^^^^^^^^^^^^^^^^^^^^^^^^^^^^^^^^^^^^
  File "H:\web\django\lesson_1\myapp\views.py", line 154, in product_add_image
    image = form.cleaned_data['image']
            ^^^^^^^^^^^^^^^^^
AttributeError: 'ImageForm' object has no attribute 'cleaned_data'. Did you mean: 'changed_data'?
ERROR 2024-02-05 19:03:52,581 basehttp 2428 28060 "POST /product/4/form_image/ HTTP/1.1" 500 69038
INFO 2024-02-05 19:07:44,048 autoreload 2428 12480 H:\web\django\lesson_1\lesson_1\settings.py changed, reloading.
INFO 2024-02-05 19:07:45,076 autoreload 1132 19268 Watching for file changes with StatReloader
INFO 2024-02-05 19:08:33,771 autoreload 1132 19268 H:\web\django\lesson_1\myapp\views.py changed, reloading.
INFO 2024-02-05 19:08:34,807 autoreload 15836 2620 Watching for file changes with StatReloader
INFO 2024-02-05 19:08:40,149 basehttp 15836 14972 "GET /product/4/form_image/ HTTP/1.1" 200 785
INFO 2024-02-05 19:08:42,798 basehttp 15836 14972 "GET /product/4/form_image/ HTTP/1.1" 200 785
INFO 2024-02-05 19:08:48,754 basehttp 15836 14972 "POST /product/4/form_image/ HTTP/1.1" 200 785
INFO 2024-02-05 19:11:11,717 autoreload 15836 2620 H:\web\django\lesson_1\myapp\views.py changed, reloading.
INFO 2024-02-05 19:11:12,757 autoreload 21528 14376 Watching for file changes with StatReloader
INFO 2024-02-05 19:11:18,069 autoreload 21528 14376 H:\web\django\lesson_1\myapp\views.py changed, reloading.
INFO 2024-02-05 19:11:19,089 autoreload 14300 30776 Watching for file changes with StatReloader
ERROR 2024-02-05 19:11:29,270 log 14300 14640 Internal Server Error: /product/4/form_image/
Traceback (most recent call last):
  File "C:\Users\pk\anaconda3\envs\django\Lib\site-packages\django\utils\datastructures.py", line 84, in __getitem__
    list_ = super().__getitem__(key)
            ^^^^^^^^^^^^^^^^^^^^^^^^
KeyError: 'image'

During handling of the above exception, another exception occurred:

Traceback (most recent call last):
  File "C:\Users\pk\anaconda3\envs\django\Lib\site-packages\django\core\handlers\exception.py", line 55, in inner
    response = get_response(request)
               ^^^^^^^^^^^^^^^^^^^^^
  File "C:\Users\pk\anaconda3\envs\django\Lib\site-packages\django\core\handlers\base.py", line 197, in _get_response
    response = wrapped_callback(request, *callback_args, **callback_kwargs)
               ^^^^^^^^^^^^^^^^^^^^^^^^^^^^^^^^^^^^^^^^^^^^^^^^^^^^^^^^^^^^
  File "H:\web\django\lesson_1\myapp\views.py", line 155, in product_add_image
    logger.info('image'+form.data['image'])
                        ~~~~~~~~~^^^^^^^^^
  File "C:\Users\pk\anaconda3\envs\django\Lib\site-packages\django\utils\datastructures.py", line 86, in __getitem__
    raise MultiValueDictKeyError(key)
django.utils.datastructures.MultiValueDictKeyError: 'image'
INFO 2024-02-05 19:11:29,277 basehttp 14300 14640 - Broken pipe from ('127.0.0.1', 62175)
ERROR 2024-02-05 19:11:29,304 log 14300 32328 Internal Server Error: /product/4/form_image/
Traceback (most recent call last):
  File "C:\Users\pk\anaconda3\envs\django\Lib\site-packages\django\utils\datastructures.py", line 84, in __getitem__
    list_ = super().__getitem__(key)
            ^^^^^^^^^^^^^^^^^^^^^^^^
KeyError: 'image'

During handling of the above exception, another exception occurred:

Traceback (most recent call last):
  File "C:\Users\pk\anaconda3\envs\django\Lib\site-packages\django\core\handlers\exception.py", line 55, in inner
    response = get_response(request)
               ^^^^^^^^^^^^^^^^^^^^^
  File "C:\Users\pk\anaconda3\envs\django\Lib\site-packages\django\core\handlers\base.py", line 197, in _get_response
    response = wrapped_callback(request, *callback_args, **callback_kwargs)
               ^^^^^^^^^^^^^^^^^^^^^^^^^^^^^^^^^^^^^^^^^^^^^^^^^^^^^^^^^^^^
  File "H:\web\django\lesson_1\myapp\views.py", line 155, in product_add_image
    logger.info('image'+form.data['image'])
                        ~~~~~~~~~^^^^^^^^^
  File "C:\Users\pk\anaconda3\envs\django\Lib\site-packages\django\utils\datastructures.py", line 86, in __getitem__
    raise MultiValueDictKeyError(key)
django.utils.datastructures.MultiValueDictKeyError: 'image'
ERROR 2024-02-05 19:11:29,308 basehttp 14300 32328 "POST /product/4/form_image/ HTTP/1.1" 500 77272
INFO 2024-02-05 19:11:50,806 autoreload 14300 30776 H:\web\django\lesson_1\myapp\views.py changed, reloading.
INFO 2024-02-05 19:11:51,831 autoreload 34800 16800 Watching for file changes with StatReloader
ERROR 2024-02-05 19:11:52,319 log 34800 33804 Internal Server Error: /product/4/form_image/
Traceback (most recent call last):
  File "C:\Users\pk\anaconda3\envs\django\Lib\site-packages\django\utils\datastructures.py", line 84, in __getitem__
    list_ = super().__getitem__(key)
            ^^^^^^^^^^^^^^^^^^^^^^^^
KeyError: 'image'

During handling of the above exception, another exception occurred:

Traceback (most recent call last):
  File "C:\Users\pk\anaconda3\envs\django\Lib\site-packages\django\core\handlers\exception.py", line 55, in inner
    response = get_response(request)
               ^^^^^^^^^^^^^^^^^^^^^
  File "C:\Users\pk\anaconda3\envs\django\Lib\site-packages\django\core\handlers\base.py", line 197, in _get_response
    response = wrapped_callback(request, *callback_args, **callback_kwargs)
               ^^^^^^^^^^^^^^^^^^^^^^^^^^^^^^^^^^^^^^^^^^^^^^^^^^^^^^^^^^^^
  File "H:\web\django\lesson_1\myapp\views.py", line 155, in product_add_image
    logger.info('image'+form.data['image'])
                        ~~~~~~~~~^^^^^^^^^
  File "C:\Users\pk\anaconda3\envs\django\Lib\site-packages\django\utils\datastructures.py", line 86, in __getitem__
    raise MultiValueDictKeyError(key)
django.utils.datastructures.MultiValueDictKeyError: 'image'
ERROR 2024-02-05 19:11:52,323 basehttp 34800 33804 "POST /product/4/form_image/ HTTP/1.1" 500 77267
INFO 2024-02-05 19:12:04,802 autoreload 34800 16800 H:\web\django\lesson_1\myapp\views.py changed, reloading.
INFO 2024-02-05 19:12:05,844 autoreload 3276 316 Watching for file changes with StatReloader
ERROR 2024-02-05 19:12:09,576 log 3276 17772 Internal Server Error: /product/4/form_image/
Traceback (most recent call last):
  File "C:\Users\pk\anaconda3\envs\django\Lib\site-packages\django\core\handlers\exception.py", line 55, in inner
    response = get_response(request)
               ^^^^^^^^^^^^^^^^^^^^^
  File "C:\Users\pk\anaconda3\envs\django\Lib\site-packages\django\core\handlers\base.py", line 197, in _get_response
    response = wrapped_callback(request, *callback_args, **callback_kwargs)
               ^^^^^^^^^^^^^^^^^^^^^^^^^^^^^^^^^^^^^^^^^^^^^^^^^^^^^^^^^^^^
  File "H:\web\django\lesson_1\myapp\views.py", line 155, in product_add_image
    logger.info('image'+form['image'])
                ~~~~~~~^~~~~~~~~~~~~~
TypeError: can only concatenate str (not "BoundField") to str
ERROR 2024-02-05 19:12:09,579 basehttp 3276 17772 "POST /product/4/form_image/ HTTP/1.1" 500 69095
INFO 2024-02-05 19:12:28,890 autoreload 3276 316 H:\web\django\lesson_1\myapp\views.py changed, reloading.
INFO 2024-02-05 19:12:44,579 autoreload 972 10068 Watching for file changes with StatReloader
INFO 2024-02-05 19:12:44,973 basehttp 972 10268 "POST /product/4/form_image/ HTTP/1.1" 200 785
INFO 2024-02-05 19:12:46,862 basehttp 972 10268 "POST /product/4/form_image/ HTTP/1.1" 200 785
INFO 2024-02-05 19:12:52,548 basehttp 972 10268 "POST /product/4/form_image/ HTTP/1.1" 200 785
INFO 2024-02-05 19:13:49,840 autoreload 972 10068 H:\web\django\lesson_1\myapp\views.py changed, reloading.
INFO 2024-02-05 19:13:50,823 autoreload 29604 13256 Watching for file changes with StatReloader
ERROR 2024-02-05 19:13:56,813 log 29604 23344 Internal Server Error: /product/4/form_image/
Traceback (most recent call last):
  File "C:\Users\pk\anaconda3\envs\django\Lib\site-packages\django\utils\datastructures.py", line 84, in __getitem__
    list_ = super().__getitem__(key)
            ^^^^^^^^^^^^^^^^^^^^^^^^
KeyError: 'image'

During handling of the above exception, another exception occurred:

Traceback (most recent call last):
  File "C:\Users\pk\anaconda3\envs\django\Lib\site-packages\django\core\handlers\exception.py", line 55, in inner
    response = get_response(request)
               ^^^^^^^^^^^^^^^^^^^^^
  File "C:\Users\pk\anaconda3\envs\django\Lib\site-packages\django\core\handlers\base.py", line 197, in _get_response
    response = wrapped_callback(request, *callback_args, **callback_kwargs)
               ^^^^^^^^^^^^^^^^^^^^^^^^^^^^^^^^^^^^^^^^^^^^^^^^^^^^^^^^^^^^
  File "H:\web\django\lesson_1\myapp\views.py", line 155, in product_add_image
    logger.info('image'+form.data['image'].name)
                        ~~~~~~~~~^^^^^^^^^
  File "C:\Users\pk\anaconda3\envs\django\Lib\site-packages\django\utils\datastructures.py", line 86, in __getitem__
    raise MultiValueDictKeyError(key)
django.utils.datastructures.MultiValueDictKeyError: 'image'
ERROR 2024-02-05 19:13:56,817 basehttp 29604 23344 "POST /product/4/form_image/ HTTP/1.1" 500 77279
INFO 2024-02-05 19:14:22,649 autoreload 29604 13256 H:\web\django\lesson_1\myapp\views.py changed, reloading.
INFO 2024-02-05 19:14:23,665 autoreload 34028 27104 Watching for file changes with StatReloader
ERROR 2024-02-05 19:14:23,967 log 34028 30220 Internal Server Error: /product/4/form_image/
Traceback (most recent call last):
  File "C:\Users\pk\anaconda3\envs\django\Lib\site-packages\django\utils\datastructures.py", line 84, in __getitem__
    list_ = super().__getitem__(key)
            ^^^^^^^^^^^^^^^^^^^^^^^^
KeyError: 'image'

During handling of the above exception, another exception occurred:

Traceback (most recent call last):
  File "C:\Users\pk\anaconda3\envs\django\Lib\site-packages\django\core\handlers\exception.py", line 55, in inner
    response = get_response(request)
               ^^^^^^^^^^^^^^^^^^^^^
  File "C:\Users\pk\anaconda3\envs\django\Lib\site-packages\django\core\handlers\base.py", line 197, in _get_response
    response = wrapped_callback(request, *callback_args, **callback_kwargs)
               ^^^^^^^^^^^^^^^^^^^^^^^^^^^^^^^^^^^^^^^^^^^^^^^^^^^^^^^^^^^^
  File "H:\web\django\lesson_1\myapp\views.py", line 155, in product_add_image
    logger.info('image'+form.data['image'])
                        ~~~~~~~~~^^^^^^^^^
  File "C:\Users\pk\anaconda3\envs\django\Lib\site-packages\django\utils\datastructures.py", line 86, in __getitem__
    raise MultiValueDictKeyError(key)
django.utils.datastructures.MultiValueDictKeyError: 'image'
ERROR 2024-02-05 19:14:23,972 basehttp 34028 30220 "POST /product/4/form_image/ HTTP/1.1" 500 77269
INFO 2024-02-05 19:14:58,497 autoreload 34028 27104 H:\web\django\lesson_1\myapp\views.py changed, reloading.
INFO 2024-02-05 19:14:59,554 autoreload 24516 25872 Watching for file changes with StatReloader
INFO 2024-02-05 19:15:03,720 autoreload 24516 25872 H:\web\django\lesson_1\myapp\views.py changed, reloading.
INFO 2024-02-05 19:15:04,757 autoreload 11260 7364 Watching for file changes with StatReloader
ERROR 2024-02-05 19:15:07,246 log 11260 26248 Internal Server Error: /product/4/form_image/
Traceback (most recent call last):
  File "C:\Users\pk\anaconda3\envs\django\Lib\site-packages\django\utils\datastructures.py", line 84, in __getitem__
    list_ = super().__getitem__(key)
            ^^^^^^^^^^^^^^^^^^^^^^^^
KeyError: 'image'

During handling of the above exception, another exception occurred:

Traceback (most recent call last):
  File "C:\Users\pk\anaconda3\envs\django\Lib\site-packages\django\core\handlers\exception.py", line 55, in inner
    response = get_response(request)
               ^^^^^^^^^^^^^^^^^^^^^
  File "C:\Users\pk\anaconda3\envs\django\Lib\site-packages\django\core\handlers\base.py", line 197, in _get_response
    response = wrapped_callback(request, *callback_args, **callback_kwargs)
               ^^^^^^^^^^^^^^^^^^^^^^^^^^^^^^^^^^^^^^^^^^^^^^^^^^^^^^^^^^^^
  File "H:\web\django\lesson_1\myapp\views.py", line 156, in product_add_image
    logger.info('image'+form.data['image'])
                        ~~~~~~~~~^^^^^^^^^
  File "C:\Users\pk\anaconda3\envs\django\Lib\site-packages\django\utils\datastructures.py", line 86, in __getitem__
    raise MultiValueDictKeyError(key)
django.utils.datastructures.MultiValueDictKeyError: 'image'
ERROR 2024-02-05 19:15:07,250 basehttp 11260 26248 "POST /product/4/form_image/ HTTP/1.1" 500 77233
ERROR 2024-02-05 19:15:25,614 log 11260 26248 Internal Server Error: /product/4/form_image/
Traceback (most recent call last):
  File "C:\Users\pk\anaconda3\envs\django\Lib\site-packages\django\utils\datastructures.py", line 84, in __getitem__
    list_ = super().__getitem__(key)
            ^^^^^^^^^^^^^^^^^^^^^^^^
KeyError: 'image'

During handling of the above exception, another exception occurred:

Traceback (most recent call last):
  File "C:\Users\pk\anaconda3\envs\django\Lib\site-packages\django\core\handlers\exception.py", line 55, in inner
    response = get_response(request)
               ^^^^^^^^^^^^^^^^^^^^^
  File "C:\Users\pk\anaconda3\envs\django\Lib\site-packages\django\core\handlers\base.py", line 197, in _get_response
    response = wrapped_callback(request, *callback_args, **callback_kwargs)
               ^^^^^^^^^^^^^^^^^^^^^^^^^^^^^^^^^^^^^^^^^^^^^^^^^^^^^^^^^^^^
  File "H:\web\django\lesson_1\myapp\views.py", line 156, in product_add_image
    logger.info('image'+form.data['image'])
                        ~~~~~~~~~^^^^^^^^^
  File "C:\Users\pk\anaconda3\envs\django\Lib\site-packages\django\utils\datastructures.py", line 86, in __getitem__
    raise MultiValueDictKeyError(key)
django.utils.datastructures.MultiValueDictKeyError: 'image'
ERROR 2024-02-05 19:15:25,617 basehttp 11260 26248 "POST /product/4/form_image/ HTTP/1.1" 500 77233
INFO 2024-02-05 19:15:32,190 autoreload 11260 7364 H:\web\django\lesson_1\myapp\views.py changed, reloading.
INFO 2024-02-05 19:15:33,205 autoreload 14844 25184 Watching for file changes with StatReloader
INFO 2024-02-05 19:15:35,807 basehttp 14844 14444 "POST /product/4/form_image/ HTTP/1.1" 200 785
INFO 2024-02-05 19:20:46,292 autoreload 14844 25184 H:\web\django\lesson_1\myapp\views.py changed, reloading.
INFO 2024-02-05 19:20:47,289 autoreload 18772 11500 Watching for file changes with StatReloader
INFO 2024-02-05 19:21:21,166 basehttp 18772 29380 "POST /product/4/form_image/ HTTP/1.1" 200 785
INFO 2024-02-05 19:21:47,350 autoreload 18772 11500 H:\web\django\lesson_1\myapp\views.py changed, reloading.
INFO 2024-02-05 19:21:48,364 autoreload 17728 3132 Watching for file changes with StatReloader
INFO 2024-02-05 19:21:55,424 basehttp 17728 14280 "POST /product/4/form_image/ HTTP/1.1" 200 785
INFO 2024-02-05 19:22:13,545 autoreload 17728 3132 H:\web\django\lesson_1\myapp\views.py changed, reloading.
INFO 2024-02-05 19:22:14,386 autoreload 27500 21084 Watching for file changes with StatReloader
INFO 2024-02-05 19:22:20,021 basehttp 27500 26292 "POST /product/4/form_image/ HTTP/1.1" 200 785
INFO 2024-02-05 19:23:13,238 autoreload 27500 21084 H:\web\django\lesson_1\myapp\forms.py changed, reloading.
INFO 2024-02-05 19:23:14,276 autoreload 5976 26692 Watching for file changes with StatReloader
INFO 2024-02-05 19:23:17,694 basehttp 5976 23248 "POST /product/4/form_image/ HTTP/1.1" 200 917
INFO 2024-02-05 19:23:27,322 basehttp 5976 23248 "POST /product/4/form_image/ HTTP/1.1" 200 917
INFO 2024-02-05 19:26:31,720 basehttp 5976 23248 "POST /product/4/form_image/ HTTP/1.1" 200 917
INFO 2024-02-05 19:27:32,533 autoreload 5976 26692 H:\web\django\lesson_1\myapp\views.py changed, reloading.
INFO 2024-02-05 19:27:33,673 autoreload 27592 28412 Watching for file changes with StatReloader
ERROR 2024-02-05 19:27:38,231 log 27592 24680 Internal Server Error: /product/4/form_image/
Traceback (most recent call last):
  File "C:\Users\pk\anaconda3\envs\django\Lib\site-packages\django\core\handlers\exception.py", line 55, in inner
    response = get_response(request)
               ^^^^^^^^^^^^^^^^^^^^^
  File "C:\Users\pk\anaconda3\envs\django\Lib\site-packages\django\core\handlers\base.py", line 197, in _get_response
    response = wrapped_callback(request, *callback_args, **callback_kwargs)
               ^^^^^^^^^^^^^^^^^^^^^^^^^^^^^^^^^^^^^^^^^^^^^^^^^^^^^^^^^^^^
  File "H:\web\django\lesson_1\myapp\views.py", line 155, in product_add_image
    if form.is_valid():
       ^^^^^^^^^^^^^^^
  File "C:\Users\pk\anaconda3\envs\django\Lib\site-packages\django\forms\forms.py", line 197, in is_valid
    return self.is_bound and not self.errors
                                 ^^^^^^^^^^^
  File "C:\Users\pk\anaconda3\envs\django\Lib\site-packages\django\forms\forms.py", line 192, in errors
    self.full_clean()
  File "C:\Users\pk\anaconda3\envs\django\Lib\site-packages\django\forms\forms.py", line 327, in full_clean
    self._clean_fields()
  File "C:\Users\pk\anaconda3\envs\django\Lib\site-packages\django\forms\forms.py", line 334, in _clean_fields
    value = bf.initial if field.disabled else bf.data
                                              ^^^^^^^
  File "C:\Users\pk\anaconda3\envs\django\Lib\site-packages\django\forms\boundfield.py", line 136, in data
    return self.form._widget_data_value(self.field.widget, self.html_name)
           ^^^^^^^^^^^^^^^^^^^^^^^^^^^^^^^^^^^^^^^^^^^^^^^^^^^^^^^^^^^^^^^
  File "C:\Users\pk\anaconda3\envs\django\Lib\site-packages\django\forms\forms.py", line 216, in _widget_data_value
    return widget.value_from_datadict(self.data, self.files, html_name)
           ^^^^^^^^^^^^^^^^^^^^^^^^^^^^^^^^^^^^^^^^^^^^^^^^^^^^^^^^^^^^
  File "C:\Users\pk\anaconda3\envs\django\Lib\site-packages\django\forms\widgets.py", line 291, in value_from_datadict
    return data.get(name)
           ^^^^^^^^
AttributeError: 'WSGIRequest' object has no attribute 'get'
ERROR 2024-02-05 19:27:38,237 basehttp 27592 24680 "POST /product/4/form_image/ HTTP/1.1" 500 96848
INFO 2024-02-05 19:27:57,813 autoreload 27592 28412 H:\web\django\lesson_1\myapp\views.py changed, reloading.
INFO 2024-02-05 19:27:58,811 autoreload 28236 28004 Watching for file changes with StatReloader
ERROR 2024-02-05 19:28:00,219 log 28236 32828 Internal Server Error: /product/4/form_image/
Traceback (most recent call last):
  File "C:\Users\pk\anaconda3\envs\django\Lib\site-packages\django\core\handlers\exception.py", line 55, in inner
    response = get_response(request)
               ^^^^^^^^^^^^^^^^^^^^^
  File "C:\Users\pk\anaconda3\envs\django\Lib\site-packages\django\core\handlers\base.py", line 197, in _get_response
    response = wrapped_callback(request, *callback_args, **callback_kwargs)
               ^^^^^^^^^^^^^^^^^^^^^^^^^^^^^^^^^^^^^^^^^^^^^^^^^^^^^^^^^^^^
  File "H:\web\django\lesson_1\myapp\views.py", line 153, in product_add_image
    form = ImageForm(request.IMAGES)
                     ^^^^^^^^^^^^^^
AttributeError: 'WSGIRequest' object has no attribute 'IMAGES'
ERROR 2024-02-05 19:28:00,223 basehttp 28236 32828 "POST /product/4/form_image/ HTTP/1.1" 500 69031
INFO 2024-02-05 19:28:05,131 autoreload 28236 28004 H:\web\django\lesson_1\myapp\views.py changed, reloading.
INFO 2024-02-05 19:28:06,194 autoreload 22476 5104 Watching for file changes with StatReloader
ERROR 2024-02-05 19:28:08,363 log 22476 25516 Internal Server Error: /product/4/form_image/
Traceback (most recent call last):
  File "C:\Users\pk\anaconda3\envs\django\Lib\site-packages\django\core\handlers\exception.py", line 55, in inner
    response = get_response(request)
               ^^^^^^^^^^^^^^^^^^^^^
  File "C:\Users\pk\anaconda3\envs\django\Lib\site-packages\django\core\handlers\base.py", line 197, in _get_response
    response = wrapped_callback(request, *callback_args, **callback_kwargs)
               ^^^^^^^^^^^^^^^^^^^^^^^^^^^^^^^^^^^^^^^^^^^^^^^^^^^^^^^^^^^^
  File "H:\web\django\lesson_1\myapp\views.py", line 153, in product_add_image
    form = ImageForm(request.IMAGE)
                     ^^^^^^^^^^^^^
AttributeError: 'WSGIRequest' object has no attribute 'IMAGE'
ERROR 2024-02-05 19:28:08,367 basehttp 22476 25516 "POST /product/4/form_image/ HTTP/1.1" 500 69023
INFO 2024-02-05 19:28:18,351 autoreload 22476 5104 H:\web\django\lesson_1\myapp\views.py changed, reloading.
INFO 2024-02-05 19:28:19,356 autoreload 14936 19152 Watching for file changes with StatReloader
INFO 2024-02-05 19:28:28,058 basehttp 14936 9676 "POST /product/4/form_image/ HTTP/1.1" 200 917
INFO 2024-02-05 19:28:29,645 basehttp 14936 9676 "POST /product/4/form_image/ HTTP/1.1" 200 917
INFO 2024-02-05 19:28:31,087 basehttp 14936 9676 "POST /product/4/form_image/ HTTP/1.1" 200 917
INFO 2024-02-05 19:28:38,730 basehttp 14936 9676 "POST /product/4/form_image/ HTTP/1.1" 200 917
INFO 2024-02-05 19:31:36,924 autoreload 14936 19152 H:\web\django\lesson_1\myapp\views.py changed, reloading.
INFO 2024-02-05 19:32:24,363 autoreload 27040 14328 Watching for file changes with StatReloader
INFO 2024-02-05 19:32:24,683 basehttp 27040 28576 "POST /product/4/form_image/ HTTP/1.1" 200 917
INFO 2024-02-05 19:33:42,603 autoreload 27040 14328 H:\web\django\lesson_1\myapp\views.py changed, reloading.
INFO 2024-02-05 19:33:43,643 autoreload 15072 3896 Watching for file changes with StatReloader
INFO 2024-02-05 19:33:50,032 autoreload 15072 3896 H:\web\django\lesson_1\myapp\views.py changed, reloading.
INFO 2024-02-05 19:33:51,074 autoreload 32480 28288 Watching for file changes with StatReloader
INFO 2024-02-05 19:33:56,259 autoreload 32480 28288 H:\web\django\lesson_1\myapp\views.py changed, reloading.
INFO 2024-02-05 19:33:57,292 autoreload 608 31668 Watching for file changes with StatReloader
INFO 2024-02-05 19:33:59,188 basehttp 608 24220 "POST /product/4/form_image/ HTTP/1.1" 200 1007
INFO 2024-02-05 19:34:02,858 basehttp 608 24220 "POST /product/4/form_image/ HTTP/1.1" 200 1007
INFO 2024-02-05 19:34:20,174 basehttp 608 24220 "POST /product/4/form_image/ HTTP/1.1" 200 1007
INFO 2024-02-05 19:36:12,915 autoreload 608 31668 H:\web\django\lesson_1\myapp\forms.py changed, reloading.
INFO 2024-02-05 19:36:13,958 autoreload 13344 9360 Watching for file changes with StatReloader
INFO 2024-02-05 19:36:20,242 autoreload 13344 9360 H:\web\django\lesson_1\myapp\views.py changed, reloading.
INFO 2024-02-05 19:36:21,259 autoreload 21860 16884 Watching for file changes with StatReloader
ERROR 2024-02-05 19:36:37,819 log 21860 34276 Internal Server Error: /product/4/form_image/
Traceback (most recent call last):
  File "C:\Users\pk\anaconda3\envs\django\Lib\site-packages\django\core\handlers\exception.py", line 55, in inner
    response = get_response(request)
               ^^^^^^^^^^^^^^^^^^^^^
  File "C:\Users\pk\anaconda3\envs\django\Lib\site-packages\django\core\handlers\base.py", line 197, in _get_response
    response = wrapped_callback(request, *callback_args, **callback_kwargs)
               ^^^^^^^^^^^^^^^^^^^^^^^^^^^^^^^^^^^^^^^^^^^^^^^^^^^^^^^^^^^^
  File "H:\web\django\lesson_1\myapp\views.py", line 156, in product_add_image
    logger.info('image'+form.cleaned_data['image'].name)
                        ^^^^^^^^^^^^^^^^^^^^^^^^^^^^^^^
AttributeError: 'NoneType' object has no attribute 'name'
ERROR 2024-02-05 19:36:37,822 basehttp 21860 34276 "POST /product/4/form_image/ HTTP/1.1" 500 69338
INFO 2024-02-05 19:37:41,910 autoreload 21860 16884 H:\web\django\lesson_1\myapp\forms.py changed, reloading.
INFO 2024-02-05 19:37:42,921 autoreload 21480 11500 Watching for file changes with StatReloader
INFO 2024-02-05 19:38:01,181 autoreload 21480 11500 H:\web\django\lesson_1\myapp\views.py changed, reloading.
INFO 2024-02-05 19:38:02,176 autoreload 16052 20140 Watching for file changes with StatReloader
ERROR 2024-02-05 19:38:03,807 log 16052 24828 Internal Server Error: /product/4/form_image/
Traceback (most recent call last):
  File "C:\Users\pk\anaconda3\envs\django\Lib\site-packages\django\core\handlers\exception.py", line 55, in inner
    response = get_response(request)
               ^^^^^^^^^^^^^^^^^^^^^
  File "C:\Users\pk\anaconda3\envs\django\Lib\site-packages\django\core\handlers\base.py", line 197, in _get_response
    response = wrapped_callback(request, *callback_args, **callback_kwargs)
               ^^^^^^^^^^^^^^^^^^^^^^^^^^^^^^^^^^^^^^^^^^^^^^^^^^^^^^^^^^^^
  File "H:\web\django\lesson_1\myapp\views.py", line 156, in product_add_image
    logger.info('image'+form.cleaned_data['image_l'].name)
                        ^^^^^^^^^^^^^^^^^^^^^^^^^^^^^^^^^
AttributeError: 'NoneType' object has no attribute 'name'
ERROR 2024-02-05 19:38:03,811 basehttp 16052 24828 "POST /product/4/form_image/ HTTP/1.1" 500 69356
INFO 2024-02-05 19:38:26,288 autoreload 16052 20140 H:\web\django\lesson_1\myapp\forms.py changed, reloading.
INFO 2024-02-05 19:38:27,302 autoreload 9904 28800 Watching for file changes with StatReloader
INFO 2024-02-05 19:38:34,731 autoreload 9904 28800 H:\web\django\lesson_1\myapp\views.py changed, reloading.
INFO 2024-02-05 19:38:35,766 autoreload 32192 23848 Watching for file changes with StatReloader
INFO 2024-02-05 19:38:48,744 basehttp 32192 29432 "POST /product/4/form_image/ HTTP/1.1" 200 1015
INFO 2024-02-05 19:40:05,572 basehttp 32192 29432 "POST /product/4/form_image/ HTTP/1.1" 200 1036
INFO 2024-02-05 19:40:21,805 basehttp 32192 29432 "POST /product/4/form_image/ HTTP/1.1" 200 1036
WARNING 2024-02-05 19:40:22,083 log 32192 29432 Not Found: /favicon.ico
WARNING 2024-02-05 19:40:22,084 basehttp 32192 29432 "GET /favicon.ico HTTP/1.1" 404 4539
INFO 2024-02-05 19:40:22,584 basehttp 32192 29432 "POST /product/4/form_image/ HTTP/1.1" 200 1036
WARNING 2024-02-05 19:40:22,778 log 32192 29432 Not Found: /favicon.ico
WARNING 2024-02-05 19:40:22,779 basehttp 32192 29432 "GET /favicon.ico HTTP/1.1" 404 4539
INFO 2024-02-05 19:40:28,826 basehttp 32192 29432 "POST /product/4/form_image/ HTTP/1.1" 200 957
INFO 2024-02-05 19:40:52,765 basehttp 32192 29432 "POST /product/4/form_image/ HTTP/1.1" 200 957
INFO 2024-02-05 19:40:54,391 basehttp 32192 29432 "POST /product/4/form_image/ HTTP/1.1" 200 957
INFO 2024-02-05 19:41:17,779 autoreload 32192 23848 H:\web\django\lesson_1\myapp\views.py changed, reloading.
INFO 2024-02-05 19:41:18,810 autoreload 3240 15668 Watching for file changes with StatReloader
INFO 2024-02-05 19:41:27,349 basehttp 3240 2576 "POST /product/4/form_image/ HTTP/1.1" 200 957
INFO 2024-02-08 17:31:19,045 autoreload 16000 13752 Watching for file changes with StatReloader
WARNING 2024-02-08 17:31:38,572 log 16000 25312 Not Found: /admin
WARNING 2024-02-08 17:31:38,579 basehttp 16000 25312 "GET /admin HTTP/1.1" 404 4521
WARNING 2024-02-08 17:31:38,672 log 16000 25312 Not Found: /favicon.ico
WARNING 2024-02-08 17:31:38,677 basehttp 16000 25312 "GET /favicon.ico HTTP/1.1" 404 4539
WARNING 2024-02-08 17:31:59,601 log 16000 25312 Not Found: /admin/
WARNING 2024-02-08 17:31:59,603 basehttp 16000 25312 "GET /admin/ HTTP/1.1" 404 4524
INFO 2024-02-08 17:32:48,606 autoreload 16000 13752 H:\web\django\lesson_1\lesson_1\settings.py changed, reloading.
INFO 2024-02-08 17:32:49,614 autoreload 32436 12768 Watching for file changes with StatReloader
INFO 2024-02-08 17:33:41,566 autoreload 32436 12768 H:\web\django\lesson_1\lesson_1\urls.py changed, reloading.
INFO 2024-02-08 17:33:42,582 autoreload 31072 31820 Watching for file changes with StatReloader
INFO 2024-02-08 17:33:46,918 basehttp 31072 31100 "GET /admin/ HTTP/1.1" 302 0
INFO 2024-02-08 17:33:46,972 basehttp 31072 31100 "GET /admin/login/?next=/admin/ HTTP/1.1" 200 4359
INFO 2024-02-08 17:33:47,335 basehttp 31072 31100 "GET /static/admin/css/base.css HTTP/1.1" 200 21544
INFO 2024-02-08 17:33:47,343 basehttp 31072 31100 "GET /static/admin/js/nav_sidebar.js HTTP/1.1" 200 3063
INFO 2024-02-08 17:33:47,550 basehttp 31072 26740 "GET /static/admin/css/responsive.css HTTP/1.1" 200 17905
INFO 2024-02-08 17:33:47,622 basehttp 31072 15216 "GET /static/admin/css/login.css HTTP/1.1" 200 958
INFO 2024-02-08 17:33:47,638 basehttp 31072 26748 "GET /static/admin/css/nav_sidebar.css HTTP/1.1" 200 2810
INFO 2024-02-08 17:33:47,669 basehttp 31072 28168 "GET /static/admin/js/theme.js HTTP/1.1" 200 1943
INFO 2024-02-08 17:33:47,710 basehttp 31072 3176 "GET /static/admin/css/dark_mode.css HTTP/1.1" 200 2682
INFO 2024-02-08 17:33:59,167 basehttp 31072 3176 "POST /admin/login/?next=/admin/ HTTP/1.1" 302 0
INFO 2024-02-08 17:33:59,222 basehttp 31072 3176 "GET /admin/ HTTP/1.1" 200 7509
INFO 2024-02-08 17:33:59,270 basehttp 31072 3176 "GET /static/admin/css/dashboard.css HTTP/1.1" 200 441
INFO 2024-02-08 17:33:59,282 basehttp 31072 28168 "GET /static/admin/img/icon-changelink.svg HTTP/1.1" 200 380
INFO 2024-02-08 17:33:59,283 basehttp 31072 3176 "GET /static/admin/img/icon-addlink.svg HTTP/1.1" 200 331
INFO 2024-02-08 17:34:04,333 basehttp 31072 28168 "GET /admin/auth/group/add/ HTTP/1.1" 200 14024
INFO 2024-02-08 17:34:04,370 basehttp 31072 28168 "GET /static/admin/css/forms.css HTTP/1.1" 200 9090
INFO 2024-02-08 17:34:04,385 basehttp 31072 15216 "GET /static/admin/js/jquery.init.js HTTP/1.1" 200 347
INFO 2024-02-08 17:34:04,388 basehttp 31072 31100 "GET /static/admin/js/admin/RelatedObjectLookups.js HTTP/1.1" 200 9042
INFO 2024-02-08 17:34:04,392 basehttp 31072 28168 "GET /static/admin/js/SelectBox.js HTTP/1.1" 200 4530
INFO 2024-02-08 17:34:04,393 basehttp 31072 26740 "GET /static/admin/js/core.js HTTP/1.1" 200 6208
INFO 2024-02-08 17:34:04,399 basehttp 31072 3176 "GET /admin/jsi18n/ HTTP/1.1" 200 17546
INFO 2024-02-08 17:34:04,401 basehttp 31072 15216 "GET /static/admin/css/widgets.css HTTP/1.1" 200 11800
INFO 2024-02-08 17:34:04,402 basehttp 31072 31100 "GET /static/admin/js/actions.js HTTP/1.1" 200 8067
INFO 2024-02-08 17:34:04,404 basehttp 31072 26740 "GET /static/admin/js/urlify.js HTTP/1.1" 200 7887
INFO 2024-02-08 17:34:04,405 basehttp 31072 28168 "GET /static/admin/js/SelectFilter2.js HTTP/1.1" 200 15492
INFO 2024-02-08 17:34:04,408 basehttp 31072 3176 "GET /static/admin/js/prepopulate.js HTTP/1.1" 200 1531
INFO 2024-02-08 17:34:04,410 basehttp 31072 31100 "GET /static/admin/js/prepopulate_init.js HTTP/1.1" 200 586
INFO 2024-02-08 17:34:04,412 basehttp 31072 26748 "GET /static/admin/js/vendor/jquery/jquery.js HTTP/1.1" 200 285314
INFO 2024-02-08 17:34:04,420 basehttp 31072 15216 "GET /static/admin/js/vendor/xregexp/xregexp.js HTTP/1.1" 200 325171
INFO 2024-02-08 17:34:04,420 basehttp 31072 26748 "GET /static/admin/js/change_form.js HTTP/1.1" 200 606
INFO 2024-02-08 17:34:04,517 basehttp 31072 15216 "GET /static/admin/img/search.svg HTTP/1.1" 200 458
INFO 2024-02-08 17:34:04,517 basehttp 31072 26748 "GET /static/admin/img/icon-unknown.svg HTTP/1.1" 200 655
INFO 2024-02-08 17:34:04,518 basehttp 31072 31100 "GET /static/admin/img/selector-icons.svg HTTP/1.1" 200 3291
INFO 2024-02-08 17:34:04,518 basehttp 31072 3176 "GET /static/admin/img/icon-unknown-alt.svg HTTP/1.1" 200 655
INFO 2024-02-08 17:35:25,468 basehttp 31072 3176 "POST /admin/auth/group/add/ HTTP/1.1" 302 0
INFO 2024-02-08 17:35:25,513 basehttp 31072 3176 "GET /admin/auth/group/1/change/ HTTP/1.1" 200 14593
INFO 2024-02-08 17:35:25,566 basehttp 31072 3176 "GET /admin/jsi18n/ HTTP/1.1" 200 17546
INFO 2024-02-08 17:35:25,602 basehttp 31072 3176 "GET /static/admin/img/icon-yes.svg HTTP/1.1" 200 436
INFO 2024-02-08 17:35:28,536 basehttp 31072 3176 "GET /admin/auth/user/add/ HTTP/1.1" 200 12384
INFO 2024-02-08 17:35:28,573 basehttp 31072 3176 "GET /admin/jsi18n/ HTTP/1.1" 200 17546
INFO 2024-02-08 17:36:00,768 basehttp 31072 3176 "POST /admin/auth/user/add/ HTTP/1.1" 302 0
INFO 2024-02-08 17:36:00,854 basehttp 31072 3176 "GET /admin/auth/user/2/change/ HTTP/1.1" 200 24948
INFO 2024-02-08 17:36:00,898 basehttp 31072 31100 "GET /static/admin/js/calendar.js HTTP/1.1" 200 9141
INFO 2024-02-08 17:36:00,901 basehttp 31072 3176 "GET /admin/jsi18n/ HTTP/1.1" 200 17546
INFO 2024-02-08 17:36:00,902 basehttp 31072 26748 "GET /static/admin/js/admin/DateTimeShortcuts.js HTTP/1.1" 200 19319
INFO 2024-02-08 17:36:00,979 basehttp 31072 26748 "GET /static/admin/img/icon-calendar.svg HTTP/1.1" 200 1086
INFO 2024-02-08 17:36:00,981 basehttp 31072 3176 "GET /static/admin/img/icon-clock.svg HTTP/1.1" 200 677
INFO 2024-02-08 17:36:33,788 basehttp 31072 3176 - Broken pipe from ('127.0.0.1', 52593)
ERROR 2024-02-08 17:36:33,869 log 31072 26748 Internal Server Error: /admin/auth/user/2/change/
Traceback (most recent call last):
  File "C:\Users\pk\anaconda3\envs\django\Lib\site-packages\django\db\backends\utils.py", line 105, in _execute
    return self.cursor.execute(sql, params)
           ^^^^^^^^^^^^^^^^^^^^^^^^^^^^^^^^
  File "C:\Users\pk\anaconda3\envs\django\Lib\site-packages\django\db\backends\sqlite3\base.py", line 328, in execute
    return super().execute(query, params)
           ^^^^^^^^^^^^^^^^^^^^^^^^^^^^^^
sqlite3.OperationalError: database is locked

The above exception was the direct cause of the following exception:

Traceback (most recent call last):
  File "C:\Users\pk\anaconda3\envs\django\Lib\site-packages\django\core\handlers\exception.py", line 55, in inner
    response = get_response(request)
               ^^^^^^^^^^^^^^^^^^^^^
  File "C:\Users\pk\anaconda3\envs\django\Lib\site-packages\django\core\handlers\base.py", line 197, in _get_response
    response = wrapped_callback(request, *callback_args, **callback_kwargs)
               ^^^^^^^^^^^^^^^^^^^^^^^^^^^^^^^^^^^^^^^^^^^^^^^^^^^^^^^^^^^^
  File "C:\Users\pk\anaconda3\envs\django\Lib\site-packages\django\contrib\admin\options.py", line 714, in wrapper
    return self.admin_site.admin_view(view)(*args, **kwargs)
           ^^^^^^^^^^^^^^^^^^^^^^^^^^^^^^^^^^^^^^^^^^^^^^^^^
  File "C:\Users\pk\anaconda3\envs\django\Lib\site-packages\django\utils\decorators.py", line 188, in _view_wrapper
    result = _process_exception(request, e)
             ^^^^^^^^^^^^^^^^^^^^^^^^^^^^^^
  File "C:\Users\pk\anaconda3\envs\django\Lib\site-packages\django\utils\decorators.py", line 186, in _view_wrapper
    response = view_func(request, *args, **kwargs)
               ^^^^^^^^^^^^^^^^^^^^^^^^^^^^^^^^^^^
  File "C:\Users\pk\anaconda3\envs\django\Lib\site-packages\django\views\decorators\cache.py", line 80, in _view_wrapper
    response = view_func(request, *args, **kwargs)
               ^^^^^^^^^^^^^^^^^^^^^^^^^^^^^^^^^^^
  File "C:\Users\pk\anaconda3\envs\django\Lib\site-packages\django\contrib\admin\sites.py", line 240, in inner
    return view(request, *args, **kwargs)
           ^^^^^^^^^^^^^^^^^^^^^^^^^^^^^^
  File "C:\Users\pk\anaconda3\envs\django\Lib\site-packages\django\contrib\admin\options.py", line 1944, in change_view
    return self.changeform_view(request, object_id, form_url, extra_context)
           ^^^^^^^^^^^^^^^^^^^^^^^^^^^^^^^^^^^^^^^^^^^^^^^^^^^^^^^^^^^^^^^^^
  File "C:\Users\pk\anaconda3\envs\django\Lib\site-packages\django\utils\decorators.py", line 48, in _wrapper
    return bound_method(*args, **kwargs)
           ^^^^^^^^^^^^^^^^^^^^^^^^^^^^^
  File "C:\Users\pk\anaconda3\envs\django\Lib\site-packages\django\utils\decorators.py", line 188, in _view_wrapper
    result = _process_exception(request, e)
             ^^^^^^^^^^^^^^^^^^^^^^^^^^^^^^
  File "C:\Users\pk\anaconda3\envs\django\Lib\site-packages\django\utils\decorators.py", line 186, in _view_wrapper
    response = view_func(request, *args, **kwargs)
               ^^^^^^^^^^^^^^^^^^^^^^^^^^^^^^^^^^^
  File "C:\Users\pk\anaconda3\envs\django\Lib\site-packages\django\contrib\admin\options.py", line 1802, in changeform_view
    return self._changeform_view(request, object_id, form_url, extra_context)
           ^^^^^^^^^^^^^^^^^^^^^^^^^^^^^^^^^^^^^^^^^^^^^^^^^^^^^^^^^^^^^^^^^^
  File "C:\Users\pk\anaconda3\envs\django\Lib\site-packages\django\contrib\admin\options.py", line 1853, in _changeform_view
    self.save_model(request, new_object, form, not add)
  File "C:\Users\pk\anaconda3\envs\django\Lib\site-packages\django\contrib\admin\options.py", line 1257, in save_model
    obj.save()
  File "C:\Users\pk\anaconda3\envs\django\Lib\site-packages\django\contrib\auth\base_user.py", line 77, in save
    super().save(*args, **kwargs)
  File "C:\Users\pk\anaconda3\envs\django\Lib\site-packages\django\db\models\base.py", line 822, in save
    self.save_base(
  File "C:\Users\pk\anaconda3\envs\django\Lib\site-packages\django\db\models\base.py", line 909, in save_base
    updated = self._save_table(
              ^^^^^^^^^^^^^^^^^
  File "C:\Users\pk\anaconda3\envs\django\Lib\site-packages\django\db\models\base.py", line 1036, in _save_table
    updated = self._do_update(
              ^^^^^^^^^^^^^^^^
  File "C:\Users\pk\anaconda3\envs\django\Lib\site-packages\django\db\models\base.py", line 1101, in _do_update
    return filtered._update(values) > 0
           ^^^^^^^^^^^^^^^^^^^^^^^^
  File "C:\Users\pk\anaconda3\envs\django\Lib\site-packages\django\db\models\query.py", line 1276, in _update
    return query.get_compiler(self.db).execute_sql(CURSOR)
           ^^^^^^^^^^^^^^^^^^^^^^^^^^^^^^^^^^^^^^^^^^^^^^^
  File "C:\Users\pk\anaconda3\envs\django\Lib\site-packages\django\db\models\sql\compiler.py", line 1990, in execute_sql
    cursor = super().execute_sql(result_type)
             ^^^^^^^^^^^^^^^^^^^^^^^^^^^^^^^^
  File "C:\Users\pk\anaconda3\envs\django\Lib\site-packages\django\db\models\sql\compiler.py", line 1562, in execute_sql
    cursor.execute(sql, params)
  File "C:\Users\pk\anaconda3\envs\django\Lib\site-packages\django\db\backends\utils.py", line 122, in execute
    return super().execute(sql, params)
           ^^^^^^^^^^^^^^^^^^^^^^^^^^^^
  File "C:\Users\pk\anaconda3\envs\django\Lib\site-packages\django\db\backends\utils.py", line 79, in execute
    return self._execute_with_wrappers(
           ^^^^^^^^^^^^^^^^^^^^^^^^^^^^
  File "C:\Users\pk\anaconda3\envs\django\Lib\site-packages\django\db\backends\utils.py", line 92, in _execute_with_wrappers
    return executor(sql, params, many, context)
           ^^^^^^^^^^^^^^^^^^^^^^^^^^^^^^^^^^^^
  File "C:\Users\pk\anaconda3\envs\django\Lib\site-packages\django\db\backends\utils.py", line 100, in _execute
    with self.db.wrap_database_errors:
  File "C:\Users\pk\anaconda3\envs\django\Lib\site-packages\django\db\utils.py", line 91, in __exit__
    raise dj_exc_value.with_traceback(traceback) from exc_value
  File "C:\Users\pk\anaconda3\envs\django\Lib\site-packages\django\db\backends\utils.py", line 105, in _execute
    return self.cursor.execute(sql, params)
           ^^^^^^^^^^^^^^^^^^^^^^^^^^^^^^^^
  File "C:\Users\pk\anaconda3\envs\django\Lib\site-packages\django\db\backends\sqlite3\base.py", line 328, in execute
    return super().execute(query, params)
           ^^^^^^^^^^^^^^^^^^^^^^^^^^^^^^
django.db.utils.OperationalError: database is locked
ERROR 2024-02-08 17:36:33,886 basehttp 31072 26748 "POST /admin/auth/user/2/change/ HTTP/1.1" 500 217855
INFO 2024-02-08 17:37:31,312 basehttp 31072 26748 "GET /admin/auth/user/2/change/ HTTP/1.1" 200 24664
INFO 2024-02-08 17:37:53,745 basehttp 31072 26748 "GET /admin/auth/user/ HTTP/1.1" 200 13872
INFO 2024-02-08 17:37:53,794 basehttp 31072 26748 "GET /static/admin/css/changelists.css HTTP/1.1" 200 6811
INFO 2024-02-08 17:37:53,797 basehttp 31072 31100 "GET /admin/jsi18n/ HTTP/1.1" 200 17546
INFO 2024-02-08 17:37:53,802 basehttp 31072 26748 "GET /static/admin/js/filters.js HTTP/1.1" 200 978
INFO 2024-02-08 17:37:53,831 basehttp 31072 26748 "GET /static/admin/img/tooltag-add.svg HTTP/1.1" 200 331
INFO 2024-02-08 17:37:53,833 basehttp 31072 31100 "GET /static/admin/img/sorting-icons.svg HTTP/1.1" 200 1097
INFO 2024-02-08 17:37:53,833 basehttp 31072 15216 "GET /static/admin/img/icon-viewlink.svg HTTP/1.1" 200 581
INFO 2024-02-08 17:37:54,608 basehttp 31072 15216 "GET /admin/auth/ HTTP/1.1" 200 6010
INFO 2024-02-08 17:37:56,840 basehttp 31072 15216 "GET /admin/ HTTP/1.1" 200 8638
INFO 2024-02-08 17:37:57,801 basehttp 31072 15216 "GET /admin/myapp/customer/ HTTP/1.1" 200 17233
INFO 2024-02-08 17:37:57,843 basehttp 31072 15216 "GET /admin/jsi18n/ HTTP/1.1" 200 17546
INFO 2024-02-08 17:38:19,800 basehttp 31072 15216 "GET /admin/myapp/order/ HTTP/1.1" 200 27131
INFO 2024-02-08 17:38:19,859 basehttp 31072 15216 "GET /admin/jsi18n/ HTTP/1.1" 200 17546
INFO 2024-02-08 17:38:26,188 basehttp 31072 15216 "GET /admin/myapp/order/49/change/ HTTP/1.1" 200 15280
INFO 2024-02-08 17:38:26,237 basehttp 31072 15216 "GET /admin/jsi18n/ HTTP/1.1" 200 17546
INFO 2024-02-08 17:38:39,999 basehttp 31072 15216 "GET /admin/myapp/customer/ HTTP/1.1" 200 17233
INFO 2024-02-08 17:38:40,040 basehttp 31072 15216 "GET /admin/jsi18n/ HTTP/1.1" 200 17546
INFO 2024-02-08 17:38:43,820 basehttp 31072 15216 "GET /admin/myapp/product/ HTTP/1.1" 200 21879
INFO 2024-02-08 17:38:43,863 basehttp 31072 15216 "GET /admin/jsi18n/ HTTP/1.1" 200 17546
INFO 2024-02-08 17:38:56,505 basehttp 31072 15216 "GET /admin/myapp/product/19/change/ HTTP/1.1" 200 13112
INFO 2024-02-08 17:38:56,543 basehttp 31072 15216 "GET /admin/jsi18n/ HTTP/1.1" 200 17546
INFO 2024-02-08 17:39:57,386 autoreload 31072 31820 H:\web\django\lesson_1\lesson_1\urls.py changed, reloading.
INFO 2024-02-08 17:39:58,427 autoreload 30268 32220 Watching for file changes with StatReloader
