INFO 2024-01-29 20:53:44,013 autoreload 12332 33020 H:\web\django\lesson_1\myapp\urls.py changed, reloading.
INFO 2024-01-29 20:53:45,117 autoreload 2856 11780 Watching for file changes with StatReloader
ERROR 2024-01-29 20:53:46,435 log 2856 15392 Internal Server Error: /
Traceback (most recent call last):
  File "C:\Users\pk\anaconda3\envs\django\Lib\site-packages\django\core\handlers\exception.py", line 55, in inner
    response = get_response(request)
               ^^^^^^^^^^^^^^^^^^^^^
  File "C:\Users\pk\anaconda3\envs\django\Lib\site-packages\django\core\handlers\base.py", line 197, in _get_response
    response = wrapped_callback(request, *callback_args, **callback_kwargs)
               ^^^^^^^^^^^^^^^^^^^^^^^^^^^^^^^^^^^^^^^^^^^^^^^^^^^^^^^^^^^^
  File "H:\web\django\lesson_1\myapp\views.py", line 58, in homepage
    return render(request, 'homepage.html', context)
           ^^^^^^^^^^^^^^^^^^^^^^^^^^^^^^^^^^^^^^^^^
  File "C:\Users\pk\anaconda3\envs\django\Lib\site-packages\django\shortcuts.py", line 24, in render
    content = loader.render_to_string(template_name, context, request, using=using)
              ^^^^^^^^^^^^^^^^^^^^^^^^^^^^^^^^^^^^^^^^^^^^^^^^^^^^^^^^^^^^^^^^^^^^^
  File "C:\Users\pk\anaconda3\envs\django\Lib\site-packages\django\template\loader.py", line 62, in render_to_string
    return template.render(context, request)
           ^^^^^^^^^^^^^^^^^^^^^^^^^^^^^^^^^
  File "C:\Users\pk\anaconda3\envs\django\Lib\site-packages\django\template\backends\django.py", line 61, in render
    return self.template.render(context)
           ^^^^^^^^^^^^^^^^^^^^^^^^^^^^^
  File "C:\Users\pk\anaconda3\envs\django\Lib\site-packages\django\template\base.py", line 171, in render
    return self._render(context)
           ^^^^^^^^^^^^^^^^^^^^^
  File "C:\Users\pk\anaconda3\envs\django\Lib\site-packages\django\template\base.py", line 163, in _render
    return self.nodelist.render(context)
           ^^^^^^^^^^^^^^^^^^^^^^^^^^^^^
  File "C:\Users\pk\anaconda3\envs\django\Lib\site-packages\django\template\base.py", line 1000, in render
    return SafeString("".join([node.render_annotated(context) for node in self]))
                               ^^^^^^^^^^^^^^^^^^^^^^^^^^^^^^
  File "C:\Users\pk\anaconda3\envs\django\Lib\site-packages\django\template\base.py", line 961, in render_annotated
    return self.render(context)
           ^^^^^^^^^^^^^^^^^^^^
  File "C:\Users\pk\anaconda3\envs\django\Lib\site-packages\django\template\loader_tags.py", line 159, in render
    return compiled_parent._render(context)
           ^^^^^^^^^^^^^^^^^^^^^^^^^^^^^^^^
  File "C:\Users\pk\anaconda3\envs\django\Lib\site-packages\django\template\base.py", line 163, in _render
    return self.nodelist.render(context)
           ^^^^^^^^^^^^^^^^^^^^^^^^^^^^^
  File "C:\Users\pk\anaconda3\envs\django\Lib\site-packages\django\template\base.py", line 1000, in render
    return SafeString("".join([node.render_annotated(context) for node in self]))
                               ^^^^^^^^^^^^^^^^^^^^^^^^^^^^^^
  File "C:\Users\pk\anaconda3\envs\django\Lib\site-packages\django\template\base.py", line 961, in render_annotated
    return self.render(context)
           ^^^^^^^^^^^^^^^^^^^^
  File "C:\Users\pk\anaconda3\envs\django\Lib\site-packages\django\template\loader_tags.py", line 65, in render
    result = block.nodelist.render(context)
             ^^^^^^^^^^^^^^^^^^^^^^^^^^^^^^
  File "C:\Users\pk\anaconda3\envs\django\Lib\site-packages\django\template\base.py", line 1000, in render
    return SafeString("".join([node.render_annotated(context) for node in self]))
                               ^^^^^^^^^^^^^^^^^^^^^^^^^^^^^^
  File "C:\Users\pk\anaconda3\envs\django\Lib\site-packages\django\template\base.py", line 961, in render_annotated
    return self.render(context)
           ^^^^^^^^^^^^^^^^^^^^
  File "C:\Users\pk\anaconda3\envs\django\Lib\site-packages\django\template\defaulttags.py", line 478, in render
    url = reverse(view_name, args=args, kwargs=kwargs, current_app=current_app)
          ^^^^^^^^^^^^^^^^^^^^^^^^^^^^^^^^^^^^^^^^^^^^^^^^^^^^^^^^^^^^^^^^^^^^^
  File "C:\Users\pk\anaconda3\envs\django\Lib\site-packages\django\urls\base.py", line 88, in reverse
    return resolver._reverse_with_prefix(view, prefix, *args, **kwargs)
           ^^^^^^^^^^^^^^^^^^^^^^^^^^^^^^^^^^^^^^^^^^^^^^^^^^^^^^^^^^^^
  File "C:\Users\pk\anaconda3\envs\django\Lib\site-packages\django\urls\resolvers.py", line 848, in _reverse_with_prefix
    raise NoReverseMatch(msg)
django.urls.exceptions.NoReverseMatch: Reverse for 'myapp.views.CustomerCreate' not found. 'myapp.views.CustomerCreate' is not a valid view function or pattern name.
ERROR 2024-01-29 20:53:46,453 basehttp 2856 15392 "GET / HTTP/1.1" 500 148435
WARNING 2024-01-29 20:53:46,506 log 2856 15392 Not Found: /favicon.ico
INFO 2024-01-29 20:53:46,506 basehttp 2856 15392 - Broken pipe from ('127.0.0.1', 50444)
ERROR 2024-01-29 20:54:15,936 log 2856 34100 Internal Server Error: /
Traceback (most recent call last):
  File "C:\Users\pk\anaconda3\envs\django\Lib\site-packages\django\core\handlers\exception.py", line 55, in inner
    response = get_response(request)
               ^^^^^^^^^^^^^^^^^^^^^
  File "C:\Users\pk\anaconda3\envs\django\Lib\site-packages\django\core\handlers\base.py", line 197, in _get_response
    response = wrapped_callback(request, *callback_args, **callback_kwargs)
               ^^^^^^^^^^^^^^^^^^^^^^^^^^^^^^^^^^^^^^^^^^^^^^^^^^^^^^^^^^^^
  File "H:\web\django\lesson_1\myapp\views.py", line 58, in homepage
    return render(request, 'homepage.html', context)
           ^^^^^^^^^^^^^^^^^^^^^^^^^^^^^^^^^^^^^^^^^
  File "C:\Users\pk\anaconda3\envs\django\Lib\site-packages\django\shortcuts.py", line 24, in render
    content = loader.render_to_string(template_name, context, request, using=using)
              ^^^^^^^^^^^^^^^^^^^^^^^^^^^^^^^^^^^^^^^^^^^^^^^^^^^^^^^^^^^^^^^^^^^^^
  File "C:\Users\pk\anaconda3\envs\django\Lib\site-packages\django\template\loader.py", line 62, in render_to_string
    return template.render(context, request)
           ^^^^^^^^^^^^^^^^^^^^^^^^^^^^^^^^^
  File "C:\Users\pk\anaconda3\envs\django\Lib\site-packages\django\template\backends\django.py", line 61, in render
    return self.template.render(context)
           ^^^^^^^^^^^^^^^^^^^^^^^^^^^^^
  File "C:\Users\pk\anaconda3\envs\django\Lib\site-packages\django\template\base.py", line 171, in render
    return self._render(context)
           ^^^^^^^^^^^^^^^^^^^^^
  File "C:\Users\pk\anaconda3\envs\django\Lib\site-packages\django\template\base.py", line 163, in _render
    return self.nodelist.render(context)
           ^^^^^^^^^^^^^^^^^^^^^^^^^^^^^
  File "C:\Users\pk\anaconda3\envs\django\Lib\site-packages\django\template\base.py", line 1000, in render
    return SafeString("".join([node.render_annotated(context) for node in self]))
                               ^^^^^^^^^^^^^^^^^^^^^^^^^^^^^^
  File "C:\Users\pk\anaconda3\envs\django\Lib\site-packages\django\template\base.py", line 961, in render_annotated
    return self.render(context)
           ^^^^^^^^^^^^^^^^^^^^
  File "C:\Users\pk\anaconda3\envs\django\Lib\site-packages\django\template\loader_tags.py", line 159, in render
    return compiled_parent._render(context)
           ^^^^^^^^^^^^^^^^^^^^^^^^^^^^^^^^
  File "C:\Users\pk\anaconda3\envs\django\Lib\site-packages\django\template\base.py", line 163, in _render
    return self.nodelist.render(context)
           ^^^^^^^^^^^^^^^^^^^^^^^^^^^^^
  File "C:\Users\pk\anaconda3\envs\django\Lib\site-packages\django\template\base.py", line 1000, in render
    return SafeString("".join([node.render_annotated(context) for node in self]))
                               ^^^^^^^^^^^^^^^^^^^^^^^^^^^^^^
  File "C:\Users\pk\anaconda3\envs\django\Lib\site-packages\django\template\base.py", line 961, in render_annotated
    return self.render(context)
           ^^^^^^^^^^^^^^^^^^^^
  File "C:\Users\pk\anaconda3\envs\django\Lib\site-packages\django\template\loader_tags.py", line 65, in render
    result = block.nodelist.render(context)
             ^^^^^^^^^^^^^^^^^^^^^^^^^^^^^^
  File "C:\Users\pk\anaconda3\envs\django\Lib\site-packages\django\template\base.py", line 1000, in render
    return SafeString("".join([node.render_annotated(context) for node in self]))
                               ^^^^^^^^^^^^^^^^^^^^^^^^^^^^^^
  File "C:\Users\pk\anaconda3\envs\django\Lib\site-packages\django\template\base.py", line 961, in render_annotated
    return self.render(context)
           ^^^^^^^^^^^^^^^^^^^^
  File "C:\Users\pk\anaconda3\envs\django\Lib\site-packages\django\template\defaulttags.py", line 478, in render
    url = reverse(view_name, args=args, kwargs=kwargs, current_app=current_app)
          ^^^^^^^^^^^^^^^^^^^^^^^^^^^^^^^^^^^^^^^^^^^^^^^^^^^^^^^^^^^^^^^^^^^^^
  File "C:\Users\pk\anaconda3\envs\django\Lib\site-packages\django\urls\base.py", line 88, in reverse
    return resolver._reverse_with_prefix(view, prefix, *args, **kwargs)
           ^^^^^^^^^^^^^^^^^^^^^^^^^^^^^^^^^^^^^^^^^^^^^^^^^^^^^^^^^^^^
  File "C:\Users\pk\anaconda3\envs\django\Lib\site-packages\django\urls\resolvers.py", line 848, in _reverse_with_prefix
    raise NoReverseMatch(msg)
django.urls.exceptions.NoReverseMatch: Reverse for 'myapp.views.create_customer' not found. 'myapp.views.create_customer' is not a valid view function or pattern name.
ERROR 2024-01-29 20:54:15,954 basehttp 2856 34100 "GET / HTTP/1.1" 500 148461
INFO 2024-01-29 20:54:31,482 basehttp 2856 34100 "GET / HTTP/1.1" 200 601
INFO 2024-01-29 20:55:24,894 autoreload 2856 11780 H:\web\django\lesson_1\myapp\urls.py changed, reloading.
INFO 2024-01-29 20:55:28,260 autoreload 1108 29940 Watching for file changes with StatReloader
INFO 2024-01-29 20:55:28,778 basehttp 1108 7316 "GET / HTTP/1.1" 200 711
WARNING 2024-01-29 20:55:28,909 log 1108 7316 Not Found: /favicon.ico
WARNING 2024-01-29 20:55:28,909 basehttp 1108 7316 "GET /favicon.ico HTTP/1.1" 404 4104
ERROR 2024-01-29 20:55:31,214 log 1108 7316 Internal Server Error: /create_customer/
Traceback (most recent call last):
  File "C:\Users\pk\anaconda3\envs\django\Lib\site-packages\django\core\handlers\exception.py", line 55, in inner
    response = get_response(request)
               ^^^^^^^^^^^^^^^^^^^^^
  File "C:\Users\pk\anaconda3\envs\django\Lib\site-packages\django\core\handlers\base.py", line 220, in _get_response
    response = response.render()
               ^^^^^^^^^^^^^^^^^
  File "C:\Users\pk\anaconda3\envs\django\Lib\site-packages\django\template\response.py", line 114, in render
    self.content = self.rendered_content
                   ^^^^^^^^^^^^^^^^^^^^^
  File "C:\Users\pk\anaconda3\envs\django\Lib\site-packages\django\template\response.py", line 90, in rendered_content
    template = self.resolve_template(self.template_name)
               ^^^^^^^^^^^^^^^^^^^^^^^^^^^^^^^^^^^^^^^^^
  File "C:\Users\pk\anaconda3\envs\django\Lib\site-packages\django\template\response.py", line 72, in resolve_template
    return select_template(template, using=self.using)
           ^^^^^^^^^^^^^^^^^^^^^^^^^^^^^^^^^^^^^^^^^^^
  File "C:\Users\pk\anaconda3\envs\django\Lib\site-packages\django\template\loader.py", line 47, in select_template
    raise TemplateDoesNotExist(", ".join(template_name_list), chain=chain)
django.template.exceptions.TemplateDoesNotExist: myapp/customer_form.html
ERROR 2024-01-29 20:55:31,214 basehttp 1108 7316 "GET /create_customer/ HTTP/1.1" 500 81345
ERROR 2024-01-29 21:02:54,260 log 1108 17136 Internal Server Error: /create_customer/
Traceback (most recent call last):
  File "C:\Users\pk\anaconda3\envs\django\Lib\site-packages\django\core\handlers\exception.py", line 55, in inner
    response = get_response(request)
               ^^^^^^^^^^^^^^^^^^^^^
  File "C:\Users\pk\anaconda3\envs\django\Lib\site-packages\django\core\handlers\base.py", line 220, in _get_response
    response = response.render()
               ^^^^^^^^^^^^^^^^^
  File "C:\Users\pk\anaconda3\envs\django\Lib\site-packages\django\template\response.py", line 114, in render
    self.content = self.rendered_content
                   ^^^^^^^^^^^^^^^^^^^^^
  File "C:\Users\pk\anaconda3\envs\django\Lib\site-packages\django\template\response.py", line 90, in rendered_content
    template = self.resolve_template(self.template_name)
               ^^^^^^^^^^^^^^^^^^^^^^^^^^^^^^^^^^^^^^^^^
  File "C:\Users\pk\anaconda3\envs\django\Lib\site-packages\django\template\response.py", line 72, in resolve_template
    return select_template(template, using=self.using)
           ^^^^^^^^^^^^^^^^^^^^^^^^^^^^^^^^^^^^^^^^^^^
  File "C:\Users\pk\anaconda3\envs\django\Lib\site-packages\django\template\loader.py", line 47, in select_template
    raise TemplateDoesNotExist(", ".join(template_name_list), chain=chain)
django.template.exceptions.TemplateDoesNotExist: myapp/customer_form.html
ERROR 2024-01-29 21:02:54,264 basehttp 1108 17136 "GET /create_customer/ HTTP/1.1" 500 81345
WARNING 2024-01-29 21:02:54,324 log 1108 17136 Not Found: /favicon.ico
INFO 2024-01-29 21:02:54,328 basehttp 1108 17136 - Broken pipe from ('127.0.0.1', 52515)
ERROR 2024-01-29 21:03:16,514 log 1108 32808 Internal Server Error: /create_customer/
Traceback (most recent call last):
  File "C:\Users\pk\anaconda3\envs\django\Lib\site-packages\django\core\handlers\exception.py", line 55, in inner
    response = get_response(request)
               ^^^^^^^^^^^^^^^^^^^^^
  File "C:\Users\pk\anaconda3\envs\django\Lib\site-packages\django\core\handlers\base.py", line 220, in _get_response
    response = response.render()
               ^^^^^^^^^^^^^^^^^
  File "C:\Users\pk\anaconda3\envs\django\Lib\site-packages\django\template\response.py", line 114, in render
    self.content = self.rendered_content
                   ^^^^^^^^^^^^^^^^^^^^^
  File "C:\Users\pk\anaconda3\envs\django\Lib\site-packages\django\template\response.py", line 90, in rendered_content
    template = self.resolve_template(self.template_name)
               ^^^^^^^^^^^^^^^^^^^^^^^^^^^^^^^^^^^^^^^^^
  File "C:\Users\pk\anaconda3\envs\django\Lib\site-packages\django\template\response.py", line 72, in resolve_template
    return select_template(template, using=self.using)
           ^^^^^^^^^^^^^^^^^^^^^^^^^^^^^^^^^^^^^^^^^^^
  File "C:\Users\pk\anaconda3\envs\django\Lib\site-packages\django\template\loader.py", line 47, in select_template
    raise TemplateDoesNotExist(", ".join(template_name_list), chain=chain)
django.template.exceptions.TemplateDoesNotExist: myapp/customer_form.html
ERROR 2024-01-29 21:03:16,514 basehttp 1108 32808 "GET /create_customer/ HTTP/1.1" 500 81345
ERROR 2024-01-29 21:03:17,675 log 1108 32808 Internal Server Error: /create_customer/
Traceback (most recent call last):
  File "C:\Users\pk\anaconda3\envs\django\Lib\site-packages\django\core\handlers\exception.py", line 55, in inner
    response = get_response(request)
               ^^^^^^^^^^^^^^^^^^^^^
  File "C:\Users\pk\anaconda3\envs\django\Lib\site-packages\django\core\handlers\base.py", line 220, in _get_response
    response = response.render()
               ^^^^^^^^^^^^^^^^^
  File "C:\Users\pk\anaconda3\envs\django\Lib\site-packages\django\template\response.py", line 114, in render
    self.content = self.rendered_content
                   ^^^^^^^^^^^^^^^^^^^^^
  File "C:\Users\pk\anaconda3\envs\django\Lib\site-packages\django\template\response.py", line 90, in rendered_content
    template = self.resolve_template(self.template_name)
               ^^^^^^^^^^^^^^^^^^^^^^^^^^^^^^^^^^^^^^^^^
  File "C:\Users\pk\anaconda3\envs\django\Lib\site-packages\django\template\response.py", line 72, in resolve_template
    return select_template(template, using=self.using)
           ^^^^^^^^^^^^^^^^^^^^^^^^^^^^^^^^^^^^^^^^^^^
  File "C:\Users\pk\anaconda3\envs\django\Lib\site-packages\django\template\loader.py", line 47, in select_template
    raise TemplateDoesNotExist(", ".join(template_name_list), chain=chain)
django.template.exceptions.TemplateDoesNotExist: myapp/customer_form.html
ERROR 2024-01-29 21:03:17,675 basehttp 1108 32808 "GET /create_customer/ HTTP/1.1" 500 81345
ERROR 2024-01-29 21:03:17,964 log 1108 32808 Internal Server Error: /create_customer/
Traceback (most recent call last):
  File "C:\Users\pk\anaconda3\envs\django\Lib\site-packages\django\core\handlers\exception.py", line 55, in inner
    response = get_response(request)
               ^^^^^^^^^^^^^^^^^^^^^
  File "C:\Users\pk\anaconda3\envs\django\Lib\site-packages\django\core\handlers\base.py", line 220, in _get_response
    response = response.render()
               ^^^^^^^^^^^^^^^^^
  File "C:\Users\pk\anaconda3\envs\django\Lib\site-packages\django\template\response.py", line 114, in render
    self.content = self.rendered_content
                   ^^^^^^^^^^^^^^^^^^^^^
  File "C:\Users\pk\anaconda3\envs\django\Lib\site-packages\django\template\response.py", line 90, in rendered_content
    template = self.resolve_template(self.template_name)
               ^^^^^^^^^^^^^^^^^^^^^^^^^^^^^^^^^^^^^^^^^
  File "C:\Users\pk\anaconda3\envs\django\Lib\site-packages\django\template\response.py", line 72, in resolve_template
    return select_template(template, using=self.using)
           ^^^^^^^^^^^^^^^^^^^^^^^^^^^^^^^^^^^^^^^^^^^
  File "C:\Users\pk\anaconda3\envs\django\Lib\site-packages\django\template\loader.py", line 47, in select_template
    raise TemplateDoesNotExist(", ".join(template_name_list), chain=chain)
django.template.exceptions.TemplateDoesNotExist: myapp/customer_form.html
ERROR 2024-01-29 21:03:17,964 basehttp 1108 32808 "GET /create_customer/ HTTP/1.1" 500 81345
ERROR 2024-01-29 21:03:18,698 log 1108 29644 Internal Server Error: /create_customer/
Traceback (most recent call last):
  File "C:\Users\pk\anaconda3\envs\django\Lib\site-packages\django\core\handlers\exception.py", line 55, in inner
    response = get_response(request)
               ^^^^^^^^^^^^^^^^^^^^^
  File "C:\Users\pk\anaconda3\envs\django\Lib\site-packages\django\core\handlers\base.py", line 220, in _get_response
    response = response.render()
               ^^^^^^^^^^^^^^^^^
  File "C:\Users\pk\anaconda3\envs\django\Lib\site-packages\django\template\response.py", line 114, in render
    self.content = self.rendered_content
                   ^^^^^^^^^^^^^^^^^^^^^
  File "C:\Users\pk\anaconda3\envs\django\Lib\site-packages\django\template\response.py", line 90, in rendered_content
    template = self.resolve_template(self.template_name)
               ^^^^^^^^^^^^^^^^^^^^^^^^^^^^^^^^^^^^^^^^^
  File "C:\Users\pk\anaconda3\envs\django\Lib\site-packages\django\template\response.py", line 72, in resolve_template
    return select_template(template, using=self.using)
           ^^^^^^^^^^^^^^^^^^^^^^^^^^^^^^^^^^^^^^^^^^^
  File "C:\Users\pk\anaconda3\envs\django\Lib\site-packages\django\template\loader.py", line 47, in select_template
    raise TemplateDoesNotExist(", ".join(template_name_list), chain=chain)
django.template.exceptions.TemplateDoesNotExist: myapp/customer_form.html
ERROR 2024-01-29 21:03:18,698 basehttp 1108 29644 "GET /create_customer/ HTTP/1.1" 500 81610
WARNING 2024-01-29 21:03:18,751 log 1108 29644 Not Found: /favicon.ico
WARNING 2024-01-29 21:03:18,751 basehttp 1108 29644 "GET /favicon.ico HTTP/1.1" 404 4104
INFO 2024-01-29 21:03:42,083 basehttp 1108 29644 "GET /create_customer/ HTTP/1.1" 200 1187
INFO 2024-01-29 21:04:22,653 basehttp 1108 29644 "POST /create_customer/ HTTP/1.1" 302 0
INFO 2024-01-29 21:04:22,665 basehttp 1108 29644 "GET / HTTP/1.1" 200 890
INFO 2024-01-29 21:05:19,748 basehttp 1108 29644 "GET /create_product/ HTTP/1.1" 200 1192
ERROR 2024-01-29 21:05:36,183 log 1108 29644 Internal Server Error: /create_product/
Traceback (most recent call last):
  File "C:\Users\pk\anaconda3\envs\django\Lib\site-packages\django\db\backends\utils.py", line 105, in _execute
    return self.cursor.execute(sql, params)
           ^^^^^^^^^^^^^^^^^^^^^^^^^^^^^^^^
  File "C:\Users\pk\anaconda3\envs\django\Lib\site-packages\django\db\backends\sqlite3\base.py", line 328, in execute
    return super().execute(query, params)
           ^^^^^^^^^^^^^^^^^^^^^^^^^^^^^^
sqlite3.IntegrityError: NOT NULL constraint failed: myapp_product.date_added

The above exception was the direct cause of the following exception:

Traceback (most recent call last):
  File "C:\Users\pk\anaconda3\envs\django\Lib\site-packages\django\core\handlers\exception.py", line 55, in inner
    response = get_response(request)
               ^^^^^^^^^^^^^^^^^^^^^
  File "C:\Users\pk\anaconda3\envs\django\Lib\site-packages\django\core\handlers\base.py", line 197, in _get_response
    response = wrapped_callback(request, *callback_args, **callback_kwargs)
               ^^^^^^^^^^^^^^^^^^^^^^^^^^^^^^^^^^^^^^^^^^^^^^^^^^^^^^^^^^^^
  File "C:\Users\pk\anaconda3\envs\django\Lib\site-packages\django\views\generic\base.py", line 104, in view
    return self.dispatch(request, *args, **kwargs)
           ^^^^^^^^^^^^^^^^^^^^^^^^^^^^^^^^^^^^^^^
  File "C:\Users\pk\anaconda3\envs\django\Lib\site-packages\django\views\generic\base.py", line 143, in dispatch
    return handler(request, *args, **kwargs)
           ^^^^^^^^^^^^^^^^^^^^^^^^^^^^^^^^^
  File "C:\Users\pk\anaconda3\envs\django\Lib\site-packages\django\views\generic\edit.py", line 182, in post
    return super().post(request, *args, **kwargs)
           ^^^^^^^^^^^^^^^^^^^^^^^^^^^^^^^^^^^^^^
  File "C:\Users\pk\anaconda3\envs\django\Lib\site-packages\django\views\generic\edit.py", line 151, in post
    return self.form_valid(form)
           ^^^^^^^^^^^^^^^^^^^^^
  File "C:\Users\pk\anaconda3\envs\django\Lib\site-packages\django\views\generic\edit.py", line 133, in form_valid
    self.object = form.save()
                  ^^^^^^^^^^^
  File "C:\Users\pk\anaconda3\envs\django\Lib\site-packages\django\forms\models.py", line 551, in save
    self.instance.save()
  File "C:\Users\pk\anaconda3\envs\django\Lib\site-packages\django\db\models\base.py", line 822, in save
    self.save_base(
  File "C:\Users\pk\anaconda3\envs\django\Lib\site-packages\django\db\models\base.py", line 909, in save_base
    updated = self._save_table(
              ^^^^^^^^^^^^^^^^^
  File "C:\Users\pk\anaconda3\envs\django\Lib\site-packages\django\db\models\base.py", line 1067, in _save_table
    results = self._do_insert(
              ^^^^^^^^^^^^^^^^
  File "C:\Users\pk\anaconda3\envs\django\Lib\site-packages\django\db\models\base.py", line 1108, in _do_insert
    return manager._insert(
           ^^^^^^^^^^^^^^^^
  File "C:\Users\pk\anaconda3\envs\django\Lib\site-packages\django\db\models\manager.py", line 87, in manager_method
    return getattr(self.get_queryset(), name)(*args, **kwargs)
           ^^^^^^^^^^^^^^^^^^^^^^^^^^^^^^^^^^^^^^^^^^^^^^^^^^^
  File "C:\Users\pk\anaconda3\envs\django\Lib\site-packages\django\db\models\query.py", line 1845, in _insert
    return query.get_compiler(using=using).execute_sql(returning_fields)
           ^^^^^^^^^^^^^^^^^^^^^^^^^^^^^^^^^^^^^^^^^^^^^^^^^^^^^^^^^^^^^
  File "C:\Users\pk\anaconda3\envs\django\Lib\site-packages\django\db\models\sql\compiler.py", line 1823, in execute_sql
    cursor.execute(sql, params)
  File "C:\Users\pk\anaconda3\envs\django\Lib\site-packages\django\db\backends\utils.py", line 122, in execute
    return super().execute(sql, params)
           ^^^^^^^^^^^^^^^^^^^^^^^^^^^^
  File "C:\Users\pk\anaconda3\envs\django\Lib\site-packages\django\db\backends\utils.py", line 79, in execute
    return self._execute_with_wrappers(
           ^^^^^^^^^^^^^^^^^^^^^^^^^^^^
  File "C:\Users\pk\anaconda3\envs\django\Lib\site-packages\django\db\backends\utils.py", line 92, in _execute_with_wrappers
    return executor(sql, params, many, context)
           ^^^^^^^^^^^^^^^^^^^^^^^^^^^^^^^^^^^^
  File "C:\Users\pk\anaconda3\envs\django\Lib\site-packages\django\db\backends\utils.py", line 100, in _execute
    with self.db.wrap_database_errors:
  File "C:\Users\pk\anaconda3\envs\django\Lib\site-packages\django\db\utils.py", line 91, in __exit__
    raise dj_exc_value.with_traceback(traceback) from exc_value
  File "C:\Users\pk\anaconda3\envs\django\Lib\site-packages\django\db\backends\utils.py", line 105, in _execute
    return self.cursor.execute(sql, params)
           ^^^^^^^^^^^^^^^^^^^^^^^^^^^^^^^^
  File "C:\Users\pk\anaconda3\envs\django\Lib\site-packages\django\db\backends\sqlite3\base.py", line 328, in execute
    return super().execute(query, params)
           ^^^^^^^^^^^^^^^^^^^^^^^^^^^^^^
django.db.utils.IntegrityError: NOT NULL constraint failed: myapp_product.date_added
ERROR 2024-01-29 21:05:36,198 basehttp 1108 29644 "POST /create_product/ HTTP/1.1" 500 172007
INFO 2024-01-29 21:13:48,968 autoreload 1108 29940 H:\web\django\lesson_1\myapp\models.py changed, reloading.
INFO 2024-01-29 21:13:49,965 autoreload 32968 30796 Watching for file changes with StatReloader
INFO 2024-01-29 21:15:22,632 autoreload 33064 14744 Watching for file changes with StatReloader
INFO 2024-01-29 21:15:31,893 basehttp 33064 4828 "POST /create_product/ HTTP/1.1" 302 0
INFO 2024-01-29 21:15:31,938 basehttp 33064 4828 "GET / HTTP/1.1" 200 924
WARNING 2024-01-29 21:15:32,068 log 33064 4828 Not Found: /favicon.ico
INFO 2024-01-29 21:15:32,068 basehttp 33064 4828 - Broken pipe from ('127.0.0.1', 54875)
INFO 2024-01-29 21:15:37,205 basehttp 33064 26184 "GET /create_customer/ HTTP/1.1" 200 1187
INFO 2024-01-29 21:15:52,428 basehttp 33064 26184 "POST /create_customer/ HTTP/1.1" 302 0
INFO 2024-01-29 21:15:52,443 basehttp 33064 26184 "GET / HTTP/1.1" 200 1103
